<sdf version='1.7'>
  <world name='default'>
    <light name='sun' type='directional'>
      <cast_shadows>1</cast_shadows>
      <pose>0 0 10 0 -0 0</pose>
      <diffuse>0.8 0.8 0.8 1</diffuse>
      <specular>0.2 0.2 0.2 1</specular>
      <attenuation>
        <range>1000</range>
        <constant>0.9</constant>
        <linear>0.01</linear>
        <quadratic>0.001</quadratic>
      </attenuation>
      <direction>-0.5 0.1 -0.9</direction>
      <spot>
        <inner_angle>0</inner_angle>
        <outer_angle>0</outer_angle>
        <falloff>0</falloff>
      </spot>
    </light>
    <model name='ground_plane'>
      <static>1</static>
      <link name='link'>
        <collision name='collision'>
          <geometry>
            <plane>
              <normal>0 0 1</normal>
              <size>100 100</size>
            </plane>
          </geometry>
          <surface>
            <contact>
              <collide_bitmask>65535</collide_bitmask>
              <ode/>
            </contact>
            <friction>
              <ode>
                <mu>100</mu>
                <mu2>50</mu2>
              </ode>
              <torsional>
                <ode/>
              </torsional>
            </friction>
            <bounce/>
          </surface>
          <max_contacts>10</max_contacts>
        </collision>
        <visual name='visual'>
          <cast_shadows>0</cast_shadows>
          <geometry>
            <plane>
              <normal>0 0 1</normal>
              <size>100 100</size>
            </plane>
          </geometry>
          <material>
            <script>
              <uri>file://media/materials/scripts/gazebo.material</uri>
              <name>Gazebo/Grey</name>
            </script>
          </material>
        </visual>
        <self_collide>0</self_collide>
        <enable_wind>0</enable_wind>
        <kinematic>0</kinematic>
      </link>
    </model>
    <gravity>0 0 -9.8</gravity>
    <magnetic_field>6e-06 2.3e-05 -4.2e-05</magnetic_field>
    <atmosphere type='adiabatic'/>
    <physics type='ode'>
      <max_step_size>0.001</max_step_size>
      <real_time_factor>1</real_time_factor>
      <real_time_update_rate>1000</real_time_update_rate>
    </physics>
    <scene>
      <ambient>0.4 0.4 0.4 1</ambient>
      <background>0.7 0.7 0.7 1</background>
      <shadows>1</shadows>
    </scene>
    <wind/>
    <spherical_coordinates>
      <surface_model>EARTH_WGS84</surface_model>
      <latitude_deg>0</latitude_deg>
      <longitude_deg>0</longitude_deg>
      <elevation>0</elevation>
      <heading_deg>0</heading_deg>
    </spherical_coordinates>
    <model name='b2w'>
      <link name='base'>
        <inertial>
          <pose>-0.000458 0.005261 0.000665 0 -0 0</pose>
          <mass>16</mass>
          <inertia>
            <ixx>0.0158533</ixx>
            <ixy>-3.66e-05</ixy>
            <ixz>-6.11e-05</ixz>
            <iyy>0.0377999</iyy>
            <iyz>-2.75e-05</iyz>
            <izz>0.0456542</izz>
          </inertia>
        </inertial>
        <collision name='base_collision'>
          <pose>0 0 0 0 -0 0</pose>
          <geometry>
            <box>
              <size>0.5 0.28 0.15</size>
            </box>
          </geometry>
          <max_contacts>10</max_contacts>
          <surface>
            <contact>
              <ode/>
            </contact>
            <bounce/>
            <friction>
              <torsional>
                <ode/>
              </torsional>
              <ode/>
            </friction>
          </surface>
        </collision>
        <visual name='base_visual'>
          <pose>0 0 0 0 -0 0</pose>
          <geometry>
            <mesh>
              <scale>1 1 1</scale>
              <uri>/home/sujhao/leg_ws/src/legged_control/legged_examples/legged_unitree/legged_unitree_description/meshes/b2w/trunk.dae</uri>
            </mesh>
          </geometry>
        </visual>
        <self_collide>0</self_collide>
        <enable_wind>0</enable_wind>
        <kinematic>0</kinematic>
      </link>
      <joint name='LF_HAA' type='revolute'>
        <pose relative_to='base'>0.3285 0.072 0 0.2 -0 0</pose>
        <parent>base</parent>
        <child>LF_hip</child>
        <axis>
          <xyz>1 0 0</xyz>
          <limit>
            <lower>-0.87</lower>
            <upper>0.87</upper>
            <effort>200</effort>
            <velocity>23</velocity>
          </limit>
          <dynamics>
            <damping>0.2</damping>
            <friction>0</friction>
            <spring_reference>0</spring_reference>
            <spring_stiffness>0</spring_stiffness>
          </dynamics>
        </axis>
      </joint>
      <link name='LF_hip'>
        <pose relative_to='LF_HAA'>0 0 0 0 -0 0</pose>
        <inertial>
          <pose>-0.009305 -0.010228 0.000264 0 -0 0</pose>
          <mass>0.595</mass>
          <inertia>
            <ixx>0.0026431</ixx>
            <ixy>0.00019234</ixy>
            <ixz>-6.76e-06</ixz>
            <iyy>0.0046728</iyy>
            <iyz>-7.16e-06</iyz>
            <izz>0.0034208</izz>
          </inertia>
        </inertial>
        <collision name='LF_hip_collision'>
          <pose>0 0 0 1.5708 -0 0</pose>
          <geometry>
            <cylinder>
              <length>0.05</length>
              <radius>0.07</radius>
            </cylinder>
          </geometry>
          <surface>
            <contact>
              <ode/>
            </contact>
            <friction>
              <ode>
                <mu>0.2</mu>
                <mu2>0.2</mu2>
              </ode>
              <torsional>
                <ode/>
              </torsional>
            </friction>
            <bounce/>
          </surface>
          <max_contacts>10</max_contacts>
        </collision>
        <visual name='LF_hip_visual'>
          <pose>0 0 0 0 -0 0</pose>
          <geometry>
            <mesh>
              <scale>1 1 1</scale>
              <uri>/home/sujhao/leg_ws/src/legged_control/legged_examples/legged_unitree/legged_unitree_description/meshes/b2w/hip.dae</uri>
            </mesh>
          </geometry>
          <material>
            <script>
              <name>Gazebo/DarkGrey</name>
              <uri>file://media/materials/scripts/gazebo.material</uri>
            </script>
          </material>
        </visual>
        <self_collide>0</self_collide>
        <enable_wind>0</enable_wind>
        <kinematic>0</kinematic>
      </link>
      <joint name='LF_HFE' type='revolute'>
        <pose relative_to='LF_hip'>0 0.11973 0 0 -0 0</pose>
        <parent>LF_hip</parent>
        <child>LF_thigh</child>
        <axis>
          <xyz>0 1 0</xyz>
          <limit>
            <lower>-94</lower>
            <upper>4.69</upper>
            <effort>200</effort>
            <velocity>23</velocity>
          </limit>
          <dynamics>
            <damping>0.2</damping>
            <friction>0</friction>
            <spring_reference>0</spring_reference>
            <spring_stiffness>0</spring_stiffness>
          </dynamics>
        </axis>
      </joint>
      <link name='LF_thigh'>
        <pose relative_to='LF_HFE'>0 0 0 0 -0 0</pose>
        <inertial>
          <pose>-0.004346 -0.035797 -0.044921 0 -0 0</pose>
          <mass>0.888</mass>
          <inertia>
            <ixx>0.041718</ixx>
            <ixy>0.00055623</ixy>
            <ixz>-0.0022768</ixz>
            <iyy>0.041071</iyy>
            <iyz>0.005796</iyz>
            <izz>0.0065677</izz>
          </inertia>
        </inertial>
        <collision name='LF_thigh_collision'>
          <pose>-0.015 0 -0.16 3.14159 1.4708 3.14159</pose>
          <geometry>
            <box>
              <size>0.32 0.0455 0.054</size>
            </box>
          </geometry>
          <surface>
            <contact>
              <ode>
                <kp>1e+06</kp>
                <kd>100</kd>
              </ode>
            </contact>
            <friction>
              <ode>
                <mu>0.2</mu>
                <mu2>0.2</mu2>
              </ode>
              <torsional>
                <ode/>
              </torsional>
            </friction>
            <bounce/>
          </surface>
          <max_contacts>10</max_contacts>
        </collision>
        <collision name='LF_thigh_collision_1'>
          <pose>0 -0.008 0 1.5708 -0 0</pose>
          <geometry>
            <cylinder>
              <length>0.08</length>
              <radius>0.044</radius>
            </cylinder>
          </geometry>
          <surface>
            <contact>
              <ode>
                <kp>1e+06</kp>
                <kd>100</kd>
              </ode>
            </contact>
            <friction>
              <ode>
                <mu>0.2</mu>
                <mu2>0.2</mu2>
              </ode>
              <torsional>
                <ode/>
              </torsional>
            </friction>
            <bounce/>
          </surface>
          <max_contacts>10</max_contacts>
        </collision>
        <visual name='LF_thigh_visual'>
          <pose>0 0 0 0 -0 0</pose>
          <geometry>
            <mesh>
              <scale>1 1 1</scale>
              <uri>/home/sujhao/leg_ws/src/legged_control/legged_examples/legged_unitree/legged_unitree_description/meshes/b2w/thigh.dae</uri>
            </mesh>
          </geometry>
          <material>
            <script>
              <name>Gazebo/DarkGrey</name>
              <uri>file://media/materials/scripts/gazebo.material</uri>
            </script>
          </material>
        </visual>
        <self_collide>0</self_collide>
        <enable_wind>0</enable_wind>
        <kinematic>0</kinematic>
      </link>
      <joint name='LF_KFE' type='revolute'>
        <pose relative_to='LF_thigh'>0 0 -0.32 0 -0 0</pose>
        <parent>LF_thigh</parent>
        <child>LF_calf</child>
        <axis>
          <xyz>0 1 0</xyz>
          <limit>
            <lower>-2.82</lower>
            <upper>-0.43</upper>
            <effort>320</effort>
            <velocity>14</velocity>
          </limit>
          <dynamics>
            <damping>0.2</damping>
            <friction>0</friction>
            <spring_reference>0</spring_reference>
            <spring_stiffness>0</spring_stiffness>
          </dynamics>
        </axis>
      </joint>
      <link name='LF_calf'>
        <pose relative_to='LF_KFE'>0 0 0 0 -0 0</pose>
        <inertial>
          <pose>0.006095 0.012046 -0.29122 0 -0 0</pose>
          <mass>0.151</mass>
          <inertia>
            <ixx>0.028133</ixx>
            <ixy>0.00016307</ixy>
            <ixz>-0.0010034</ixz>
            <iyy>0.029251</iyy>
            <iyz>0.0014765</iyz>
            <izz>0.0028379</izz>
          </inertia>
        </inertial>
        <collision name='LF_calf_collision'>
          <pose>0 0 -0.175 3.14159 1.57079 3.14159</pose>
          <geometry>
            <box>
              <size>0.35 0.04 0.05</size>
            </box>
          </geometry>
          <surface>
            <contact>
              <ode/>
            </contact>
            <friction>
              <ode>
                <mu>0.6</mu>
                <mu2>0.6</mu2>
              </ode>
              <torsional>
                <ode/>
              </torsional>
            </friction>
            <bounce/>
          </surface>
          <max_contacts>10</max_contacts>
        </collision>
        <visual name='LF_calf_visual'>
          <pose>0 0 0 0 -0 0</pose>
          <geometry>
            <mesh>
              <scale>1 1 1</scale>
              <uri>/home/sujhao/leg_ws/src/legged_control/legged_examples/legged_unitree/legged_unitree_description/meshes/b2w/calf.dae</uri>
            </mesh>
          </geometry>
        </visual>
        <self_collide>1</self_collide>
        <enable_wind>0</enable_wind>
        <kinematic>0</kinematic>
      </link>
      <joint name='LF_foot' type='revolute'>
        <pose relative_to='LF_calf'>0 0 -0.35 0 -0 0</pose>
        <parent>LF_calf</parent>
        <child>LF_FOOT</child>
        <axis>
          <xyz>0 1 0</xyz>
          <limit>
            <effort>20</effort>
            <velocity>50</velocity>
            <lower>-1e+16</lower>
            <upper>1e+16</upper>
          </limit>
          <dynamics>
            <damping>0.5</damping>
            <friction>0.1</friction>
            <spring_reference>0</spring_reference>
            <spring_stiffness>0</spring_stiffness>
          </dynamics>
        </axis>
        <physics>
          <ode>
            <limit>
              <cfm>0</cfm>
              <erp>0.2</erp>
            </limit>
          </ode>
        </physics>
      </joint>
      <link name='LF_FOOT'>
        <pose relative_to='LF_foot'>0 0 0 0 -0 0</pose>
        <inertial>
          <pose>0 0.051053 0 0 -0 0</pose>
          <mass>0.118</mass>
          <inertia>
            <ixx>0.004121</ixx>
            <ixy>6e-06</ixy>
            <ixz>-4.8e-05</ixz>
            <iyy>0.007776</iyy>
            <iyz>7e-06</iyz>
            <izz>0.004108</izz>
          </inertia>
        </inertial>
        <collision name='LF_FOOT_collision'>
          <pose>0 0 0 0 -0 0</pose>
          <geometry>
            <sphere>
              <radius>0.1</radius>
            </sphere>
          </geometry>
          <surface>
            <contact>
              <ode>
                <kp>1e+06</kp>
                <kd>100</kd>
              </ode>
            </contact>
            <friction>
              <ode>
                <mu>1</mu>
                <mu2>1</mu2>
              </ode>
              <torsional>
                <ode/>
              </torsional>
            </friction>
            <bounce/>
          </surface>
          <max_contacts>10</max_contacts>
        </collision>
        <visual name='LF_FOOT_visual'>
          <pose>0 0.051053 0 0 -0 0</pose>
          <geometry>
            <mesh>
              <scale>1 1 1</scale>
              <uri>/home/sujhao/leg_ws/src/legged_control/legged_examples/legged_unitree/legged_unitree_description/meshes/b2w/foot.dae</uri>
            </mesh>
          </geometry>
          <material>
            <script>
              <name>Gazebo/DarkGrey</name>
              <uri>file://media/materials/scripts/gazebo.material</uri>
            </script>
          </material>
        </visual>
        <self_collide>1</self_collide>
        <enable_wind>0</enable_wind>
        <kinematic>0</kinematic>
      </link>
      <joint name='LH_HAA' type='revolute'>
        <pose relative_to='base'>-0.3285 0.072 0 0.2 -0 0</pose>
        <parent>base</parent>
        <child>LH_hip</child>
        <axis>
          <xyz>1 0 0</xyz>
          <limit>
            <lower>-0.87</lower>
            <upper>0.87</upper>
            <effort>200</effort>
            <velocity>23</velocity>
          </limit>
          <dynamics>
            <damping>0.2</damping>
            <friction>0</friction>
            <spring_reference>0</spring_reference>
            <spring_stiffness>0</spring_stiffness>
          </dynamics>
        </axis>
      </joint>
      <link name='LH_hip'>
        <pose relative_to='LH_HAA'>0 0 0 0 -0 0</pose>
        <inertial>
          <pose>0.009305 -0.010228 0.000264 0 -0 0</pose>
          <mass>0.595</mass>
          <inertia>
            <ixx>0.0026431</ixx>
            <ixy>-0.00019234</ixy>
            <ixz>6.76e-06</ixz>
            <iyy>0.0046728</iyy>
            <iyz>-7.16e-06</iyz>
            <izz>0.0034208</izz>
          </inertia>
        </inertial>
        <collision name='LH_hip_collision'>
          <pose>0 0 0 1.5708 -0 0</pose>
          <geometry>
            <cylinder>
              <length>0.05</length>
              <radius>0.07</radius>
            </cylinder>
          </geometry>
          <surface>
            <contact>
              <ode/>
            </contact>
            <friction>
              <ode>
                <mu>0.2</mu>
                <mu2>0.2</mu2>
              </ode>
              <torsional>
                <ode/>
              </torsional>
            </friction>
            <bounce/>
          </surface>
          <max_contacts>10</max_contacts>
        </collision>
        <visual name='LH_hip_visual'>
          <pose>0 0 0 3.14159 -0 3.14159</pose>
          <geometry>
            <mesh>
              <scale>1 1 1</scale>
              <uri>/home/sujhao/leg_ws/src/legged_control/legged_examples/legged_unitree/legged_unitree_description/meshes/b2w/hip.dae</uri>
            </mesh>
          </geometry>
          <material>
            <script>
              <name>Gazebo/DarkGrey</name>
              <uri>file://media/materials/scripts/gazebo.material</uri>
            </script>
          </material>
        </visual>
        <self_collide>0</self_collide>
        <enable_wind>0</enable_wind>
        <kinematic>0</kinematic>
      </link>
      <joint name='LH_HFE' type='revolute'>
        <pose relative_to='LH_hip'>0 0.11973 0 0 -0 0</pose>
        <parent>LH_hip</parent>
        <child>LH_thigh</child>
        <axis>
          <xyz>0 1 0</xyz>
          <limit>
            <lower>-94</lower>
            <upper>4.69</upper>
            <effort>200</effort>
            <velocity>23</velocity>
          </limit>
          <dynamics>
            <damping>0.2</damping>
            <friction>0</friction>
            <spring_reference>0</spring_reference>
            <spring_stiffness>0</spring_stiffness>
          </dynamics>
        </axis>
      </joint>
      <link name='LH_thigh'>
        <pose relative_to='LH_HFE'>0 0 0 0 -0 0</pose>
        <inertial>
          <pose>-0.004346 -0.035797 -0.044921 0 -0 0</pose>
          <mass>0.888</mass>
          <inertia>
            <ixx>0.041718</ixx>
            <ixy>0.00055623</ixy>
            <ixz>-0.0022768</ixz>
            <iyy>0.041071</iyy>
            <iyz>0.005796</iyz>
            <izz>0.0065677</izz>
          </inertia>
        </inertial>
        <collision name='LH_thigh_collision'>
          <pose>-0.015 0 -0.16 3.14159 1.4708 3.14159</pose>
          <geometry>
            <box>
              <size>0.32 0.0455 0.054</size>
            </box>
          </geometry>
          <surface>
            <contact>
              <ode>
                <kp>1e+06</kp>
                <kd>100</kd>
              </ode>
            </contact>
            <friction>
              <ode>
                <mu>0.2</mu>
                <mu2>0.2</mu2>
              </ode>
              <torsional>
                <ode/>
              </torsional>
            </friction>
            <bounce/>
          </surface>
          <max_contacts>10</max_contacts>
        </collision>
        <collision name='LH_thigh_collision_1'>
          <pose>0 -0.008 0 1.5708 -0 0</pose>
          <geometry>
            <cylinder>
              <length>0.08</length>
              <radius>0.044</radius>
            </cylinder>
          </geometry>
          <surface>
            <contact>
              <ode>
                <kp>1e+06</kp>
                <kd>100</kd>
              </ode>
            </contact>
            <friction>
              <ode>
                <mu>0.2</mu>
                <mu2>0.2</mu2>
              </ode>
              <torsional>
                <ode/>
              </torsional>
            </friction>
            <bounce/>
          </surface>
          <max_contacts>10</max_contacts>
        </collision>
        <visual name='LH_thigh_visual'>
          <pose>0 0 0 0 -0 0</pose>
          <geometry>
            <mesh>
              <scale>1 1 1</scale>
              <uri>/home/sujhao/leg_ws/src/legged_control/legged_examples/legged_unitree/legged_unitree_description/meshes/b2w/thigh.dae</uri>
            </mesh>
          </geometry>
          <material>
            <script>
              <name>Gazebo/DarkGrey</name>
              <uri>file://media/materials/scripts/gazebo.material</uri>
            </script>
          </material>
        </visual>
        <self_collide>0</self_collide>
        <enable_wind>0</enable_wind>
        <kinematic>0</kinematic>
      </link>
      <joint name='LH_KFE' type='revolute'>
        <pose relative_to='LH_thigh'>0 0 -0.32 0 -0 0</pose>
        <parent>LH_thigh</parent>
        <child>LH_calf</child>
        <axis>
          <xyz>0 1 0</xyz>
          <limit>
            <lower>-2.82</lower>
            <upper>-0.43</upper>
            <effort>320</effort>
            <velocity>14</velocity>
          </limit>
          <dynamics>
            <damping>0.2</damping>
            <friction>0</friction>
            <spring_reference>0</spring_reference>
            <spring_stiffness>0</spring_stiffness>
          </dynamics>
        </axis>
      </joint>
      <link name='LH_calf'>
        <pose relative_to='LH_KFE'>0 0 0 0 -0 0</pose>
        <inertial>
          <pose>0.006095 0.012046 -0.29122 0 -0 0</pose>
          <mass>0.151</mass>
          <inertia>
            <ixx>0.028133</ixx>
            <ixy>0.00016307</ixy>
            <ixz>-0.0010034</ixz>
            <iyy>0.029251</iyy>
            <iyz>0.0014765</iyz>
            <izz>0.0028379</izz>
          </inertia>
        </inertial>
        <collision name='LH_calf_collision'>
          <pose>0 0 -0.175 3.14159 1.57079 3.14159</pose>
          <geometry>
            <box>
              <size>0.35 0.04 0.05</size>
            </box>
          </geometry>
          <surface>
            <contact>
              <ode/>
            </contact>
            <friction>
              <ode>
                <mu>0.6</mu>
                <mu2>0.6</mu2>
              </ode>
              <torsional>
                <ode/>
              </torsional>
            </friction>
            <bounce/>
          </surface>
          <max_contacts>10</max_contacts>
        </collision>
        <visual name='LH_calf_visual'>
          <pose>0 0 0 0 -0 0</pose>
          <geometry>
            <mesh>
              <scale>1 1 1</scale>
              <uri>/home/sujhao/leg_ws/src/legged_control/legged_examples/legged_unitree/legged_unitree_description/meshes/b2w/calf.dae</uri>
            </mesh>
          </geometry>
        </visual>
        <self_collide>1</self_collide>
        <enable_wind>0</enable_wind>
        <kinematic>0</kinematic>
      </link>
      <joint name='LH_foot' type='revolute'>
        <pose relative_to='LH_calf'>0 0 -0.35 0 -0 0</pose>
        <parent>LH_calf</parent>
        <child>LH_FOOT</child>
        <axis>
          <xyz>0 1 0</xyz>
          <limit>
            <effort>20</effort>
            <velocity>50</velocity>
            <lower>-1e+16</lower>
            <upper>1e+16</upper>
          </limit>
          <dynamics>
            <damping>0.5</damping>
            <friction>0.1</friction>
            <spring_reference>0</spring_reference>
            <spring_stiffness>0</spring_stiffness>
          </dynamics>
        </axis>
        <physics>
          <ode>
            <limit>
              <cfm>0</cfm>
              <erp>0.2</erp>
            </limit>
          </ode>
        </physics>
      </joint>
      <link name='LH_FOOT'>
        <pose relative_to='LH_foot'>0 0 0 0 -0 0</pose>
        <inertial>
          <pose>0 0.051053 0 0 -0 0</pose>
          <mass>0.118</mass>
          <inertia>
            <ixx>0.004121</ixx>
            <ixy>6e-06</ixy>
            <ixz>-4.8e-05</ixz>
            <iyy>0.007776</iyy>
            <iyz>7e-06</iyz>
            <izz>0.004108</izz>
          </inertia>
        </inertial>
        <collision name='LH_FOOT_collision'>
          <pose>0 0 0 0 -0 0</pose>
          <geometry>
            <sphere>
              <radius>0.1</radius>
            </sphere>
          </geometry>
          <surface>
            <contact>
              <ode>
                <kp>1e+06</kp>
                <kd>100</kd>
              </ode>
            </contact>
            <friction>
              <ode>
                <mu>1</mu>
                <mu2>1</mu2>
              </ode>
              <torsional>
                <ode/>
              </torsional>
            </friction>
            <bounce/>
          </surface>
          <max_contacts>10</max_contacts>
        </collision>
        <visual name='LH_FOOT_visual'>
          <pose>0 0.051053 0 0 -0 0</pose>
          <geometry>
            <mesh>
              <scale>1 1 1</scale>
              <uri>/home/sujhao/leg_ws/src/legged_control/legged_examples/legged_unitree/legged_unitree_description/meshes/b2w/foot.dae</uri>
            </mesh>
          </geometry>
          <material>
            <script>
              <name>Gazebo/DarkGrey</name>
              <uri>file://media/materials/scripts/gazebo.material</uri>
            </script>
          </material>
        </visual>
        <self_collide>1</self_collide>
        <enable_wind>0</enable_wind>
        <kinematic>0</kinematic>
      </link>
      <joint name='RF_HAA' type='revolute'>
        <pose relative_to='base'>0.3285 -0.072 0 -0.2 0 0</pose>
        <parent>base</parent>
        <child>RF_hip</child>
        <axis>
          <xyz>1 0 0</xyz>
          <limit>
            <lower>-0.87</lower>
            <upper>0.87</upper>
            <effort>200</effort>
            <velocity>23</velocity>
          </limit>
          <dynamics>
            <damping>0.2</damping>
            <friction>0</friction>
            <spring_reference>0</spring_reference>
            <spring_stiffness>0</spring_stiffness>
          </dynamics>
        </axis>
      </joint>
      <link name='RF_hip'>
        <pose relative_to='RF_HAA'>0 0 0 0 -0 0</pose>
        <inertial>
          <pose>-0.009305 0.010228 0.000264 0 -0 0</pose>
          <mass>0.595</mass>
          <inertia>
            <ixx>0.0026431</ixx>
            <ixy>-0.00019234</ixy>
            <ixz>-6.76e-06</ixz>
            <iyy>0.0046728</iyy>
            <iyz>7.16e-06</iyz>
            <izz>0.0034208</izz>
          </inertia>
        </inertial>
        <collision name='RF_hip_collision'>
          <pose>0 0 0 1.5708 -0 0</pose>
          <geometry>
            <cylinder>
              <length>0.05</length>
              <radius>0.07</radius>
            </cylinder>
          </geometry>
          <surface>
            <contact>
              <ode/>
            </contact>
            <friction>
              <ode>
                <mu>0.2</mu>
                <mu2>0.2</mu2>
              </ode>
              <torsional>
                <ode/>
              </torsional>
            </friction>
            <bounce/>
          </surface>
          <max_contacts>10</max_contacts>
        </collision>
        <visual name='RF_hip_visual'>
          <pose>0 0 0 3.14159 -0 0</pose>
          <geometry>
            <mesh>
              <scale>1 1 1</scale>
              <uri>/home/sujhao/leg_ws/src/legged_control/legged_examples/legged_unitree/legged_unitree_description/meshes/b2w/hip.dae</uri>
            </mesh>
          </geometry>
          <material>
            <script>
              <name>Gazebo/DarkGrey</name>
              <uri>file://media/materials/scripts/gazebo.material</uri>
            </script>
          </material>
        </visual>
        <self_collide>0</self_collide>
        <enable_wind>0</enable_wind>
        <kinematic>0</kinematic>
      </link>
      <joint name='RF_HFE' type='revolute'>
        <pose relative_to='RF_hip'>0 -0.11973 0 0 -0 0</pose>
        <parent>RF_hip</parent>
        <child>RF_thigh</child>
        <axis>
          <xyz>0 1 0</xyz>
          <limit>
            <lower>-94</lower>
            <upper>4.69</upper>
            <effort>200</effort>
            <velocity>23</velocity>
          </limit>
          <dynamics>
            <damping>0.2</damping>
            <friction>0</friction>
            <spring_reference>0</spring_reference>
            <spring_stiffness>0</spring_stiffness>
          </dynamics>
        </axis>
      </joint>
      <link name='RF_thigh'>
        <pose relative_to='RF_HFE'>0 0 0 0 -0 0</pose>
        <inertial>
          <pose>-0.004346 0.035797 -0.044921 0 -0 0</pose>
          <mass>0.888</mass>
          <inertia>
            <ixx>0.041718</ixx>
            <ixy>-0.00055623</ixy>
            <ixz>-0.0022768</ixz>
            <iyy>0.041071</iyy>
            <iyz>-0.005796</iyz>
            <izz>0.0065677</izz>
          </inertia>
        </inertial>
        <collision name='RF_thigh_collision'>
          <pose>-0.015 0 -0.16 3.14159 1.4708 3.14159</pose>
          <geometry>
            <box>
              <size>0.32 0.0455 0.054</size>
            </box>
          </geometry>
          <surface>
            <contact>
              <ode>
                <kp>1e+06</kp>
                <kd>100</kd>
              </ode>
            </contact>
            <friction>
              <ode>
                <mu>0.2</mu>
                <mu2>0.2</mu2>
              </ode>
              <torsional>
                <ode/>
              </torsional>
            </friction>
            <bounce/>
          </surface>
          <max_contacts>10</max_contacts>
        </collision>
        <collision name='RF_thigh_collision_1'>
          <pose>0 0.008 0 1.5708 -0 0</pose>
          <geometry>
            <cylinder>
              <length>0.08</length>
              <radius>0.044</radius>
            </cylinder>
          </geometry>
          <surface>
            <contact>
              <ode>
                <kp>1e+06</kp>
                <kd>100</kd>
              </ode>
            </contact>
            <friction>
              <ode>
                <mu>0.2</mu>
                <mu2>0.2</mu2>
              </ode>
              <torsional>
                <ode/>
              </torsional>
            </friction>
            <bounce/>
          </surface>
          <max_contacts>10</max_contacts>
        </collision>
        <visual name='RF_thigh_visual'>
          <pose>0 0 0 0 -0 0</pose>
          <geometry>
            <mesh>
              <scale>1 1 1</scale>
              <uri>/home/sujhao/leg_ws/src/legged_control/legged_examples/legged_unitree/legged_unitree_description/meshes/b2w/thigh_mirror.dae</uri>
            </mesh>
          </geometry>
          <material>
            <script>
              <name>Gazebo/DarkGrey</name>
              <uri>file://media/materials/scripts/gazebo.material</uri>
            </script>
          </material>
        </visual>
        <self_collide>0</self_collide>
        <enable_wind>0</enable_wind>
        <kinematic>0</kinematic>
      </link>
      <joint name='RF_KFE' type='revolute'>
        <pose relative_to='RF_thigh'>0 0 -0.32 0 -0 0</pose>
        <parent>RF_thigh</parent>
        <child>RF_calf</child>
        <axis>
          <xyz>0 1 0</xyz>
          <limit>
            <lower>-2.82</lower>
            <upper>-0.43</upper>
            <effort>320</effort>
            <velocity>14</velocity>
          </limit>
          <dynamics>
            <damping>0.2</damping>
            <friction>0</friction>
            <spring_reference>0</spring_reference>
            <spring_stiffness>0</spring_stiffness>
          </dynamics>
        </axis>
      </joint>
      <link name='RF_calf'>
        <pose relative_to='RF_KFE'>0 0 0 0 -0 0</pose>
        <inertial>
          <pose>0.006095 0.012046 -0.29122 0 -0 0</pose>
          <mass>0.151</mass>
          <inertia>
            <ixx>0.028133</ixx>
            <ixy>0.00016307</ixy>
            <ixz>-0.0010034</ixz>
            <iyy>0.029251</iyy>
            <iyz>0.0014765</iyz>
            <izz>0.0028379</izz>
          </inertia>
        </inertial>
        <collision name='RF_calf_collision'>
          <pose>0 0 -0.175 3.14159 1.57079 3.14159</pose>
          <geometry>
            <box>
              <size>0.35 0.04 0.05</size>
            </box>
          </geometry>
          <surface>
            <contact>
              <ode/>
            </contact>
            <friction>
              <ode>
                <mu>0.6</mu>
                <mu2>0.6</mu2>
              </ode>
              <torsional>
                <ode/>
              </torsional>
            </friction>
            <bounce/>
          </surface>
          <max_contacts>10</max_contacts>
        </collision>
        <visual name='RF_calf_visual'>
          <pose>0 0 0 0 -0 0</pose>
          <geometry>
            <mesh>
              <scale>1 1 1</scale>
              <uri>/home/sujhao/leg_ws/src/legged_control/legged_examples/legged_unitree/legged_unitree_description/meshes/b2w/calf_mirror.dae</uri>
            </mesh>
          </geometry>
        </visual>
        <self_collide>1</self_collide>
        <enable_wind>0</enable_wind>
        <kinematic>0</kinematic>
      </link>
      <joint name='RF_foot' type='revolute'>
        <pose relative_to='RF_calf'>0 0 -0.35 0 -0 0</pose>
        <parent>RF_calf</parent>
        <child>RF_FOOT</child>
        <axis>
          <xyz>0 1 0</xyz>
          <limit>
            <effort>20</effort>
            <velocity>50</velocity>
            <lower>-1e+16</lower>
            <upper>1e+16</upper>
          </limit>
          <dynamics>
            <damping>0.5</damping>
            <friction>0.1</friction>
            <spring_reference>0</spring_reference>
            <spring_stiffness>0</spring_stiffness>
          </dynamics>
        </axis>
        <physics>
          <ode>
            <limit>
              <cfm>0</cfm>
              <erp>0.2</erp>
            </limit>
          </ode>
        </physics>
      </joint>
      <link name='RF_FOOT'>
        <pose relative_to='RF_foot'>0 0 0 0 -0 0</pose>
        <inertial>
          <pose>0 -0.051053 0 0 -0 0</pose>
          <mass>0.118</mass>
          <inertia>
            <ixx>0.004121</ixx>
            <ixy>6e-06</ixy>
            <ixz>-4.8e-05</ixz>
            <iyy>0.007776</iyy>
            <iyz>7e-06</iyz>
            <izz>0.004108</izz>
          </inertia>
        </inertial>
        <collision name='RF_FOOT_collision'>
          <pose>0 0 0 0 -0 0</pose>
          <geometry>
            <sphere>
              <radius>0.1</radius>
            </sphere>
          </geometry>
          <surface>
            <contact>
              <ode>
                <kp>1e+06</kp>
                <kd>100</kd>
              </ode>
            </contact>
            <friction>
              <ode>
                <mu>1</mu>
                <mu2>1</mu2>
              </ode>
              <torsional>
                <ode/>
              </torsional>
            </friction>
            <bounce/>
          </surface>
          <max_contacts>10</max_contacts>
        </collision>
        <visual name='RF_FOOT_visual'>
          <pose>0 -0.051053 0 0 -0 0</pose>
          <geometry>
            <mesh>
              <scale>1 1 1</scale>
              <uri>/home/sujhao/leg_ws/src/legged_control/legged_examples/legged_unitree/legged_unitree_description/meshes/b2w/foot_mirror.dae</uri>
            </mesh>
          </geometry>
          <material>
            <script>
              <name>Gazebo/DarkGrey</name>
              <uri>file://media/materials/scripts/gazebo.material</uri>
            </script>
          </material>
        </visual>
        <self_collide>1</self_collide>
        <enable_wind>0</enable_wind>
        <kinematic>0</kinematic>
      </link>
      <joint name='RH_HAA' type='revolute'>
        <pose relative_to='base'>-0.3285 -0.072 0 -0.2 0 0</pose>
        <parent>base</parent>
        <child>RH_hip</child>
        <axis>
          <xyz>1 0 0</xyz>
          <limit>
            <lower>-0.87</lower>
            <upper>0.87</upper>
            <effort>200</effort>
            <velocity>23</velocity>
          </limit>
          <dynamics>
            <damping>0.2</damping>
            <friction>0</friction>
            <spring_reference>0</spring_reference>
            <spring_stiffness>0</spring_stiffness>
          </dynamics>
        </axis>
      </joint>
      <link name='RH_hip'>
        <pose relative_to='RH_HAA'>0 0 0 0 -0 0</pose>
        <inertial>
          <pose>0.009305 0.010228 0.000264 0 -0 0</pose>
          <mass>0.595</mass>
          <inertia>
            <ixx>0.0026431</ixx>
            <ixy>0.00019234</ixy>
            <ixz>6.76e-06</ixz>
            <iyy>0.0046728</iyy>
            <iyz>7.16e-06</iyz>
            <izz>0.0034208</izz>
          </inertia>
        </inertial>
        <collision name='RH_hip_collision'>
          <pose>0 0 0 1.5708 -0 0</pose>
          <geometry>
            <cylinder>
              <length>0.05</length>
              <radius>0.07</radius>
            </cylinder>
          </geometry>
          <surface>
            <contact>
              <ode/>
            </contact>
            <friction>
              <ode>
                <mu>0.2</mu>
                <mu2>0.2</mu2>
              </ode>
              <torsional>
                <ode/>
              </torsional>
            </friction>
            <bounce/>
          </surface>
          <max_contacts>10</max_contacts>
        </collision>
        <visual name='RH_hip_visual'>
          <pose>0 0 0 0 -0 3.14159</pose>
          <geometry>
            <mesh>
              <scale>1 1 1</scale>
              <uri>/home/sujhao/leg_ws/src/legged_control/legged_examples/legged_unitree/legged_unitree_description/meshes/b2w/hip.dae</uri>
            </mesh>
          </geometry>
          <material>
            <script>
              <name>Gazebo/DarkGrey</name>
              <uri>file://media/materials/scripts/gazebo.material</uri>
            </script>
          </material>
        </visual>
        <self_collide>0</self_collide>
        <enable_wind>0</enable_wind>
        <kinematic>0</kinematic>
      </link>
      <joint name='RH_HFE' type='revolute'>
        <pose relative_to='RH_hip'>0 -0.11973 0 0 -0 0</pose>
        <parent>RH_hip</parent>
        <child>RH_thigh</child>
        <axis>
          <xyz>0 1 0</xyz>
          <limit>
            <lower>-94</lower>
            <upper>4.69</upper>
            <effort>200</effort>
            <velocity>23</velocity>
          </limit>
          <dynamics>
            <damping>0.2</damping>
            <friction>0</friction>
            <spring_reference>0</spring_reference>
            <spring_stiffness>0</spring_stiffness>
          </dynamics>
        </axis>
      </joint>
      <link name='RH_thigh'>
        <pose relative_to='RH_HFE'>0 0 0 0 -0 0</pose>
        <inertial>
          <pose>-0.004346 0.035797 -0.044921 0 -0 0</pose>
          <mass>0.888</mass>
          <inertia>
            <ixx>0.041718</ixx>
            <ixy>-0.00055623</ixy>
            <ixz>-0.0022768</ixz>
            <iyy>0.041071</iyy>
            <iyz>-0.005796</iyz>
            <izz>0.0065677</izz>
          </inertia>
        </inertial>
        <collision name='RH_thigh_collision'>
          <pose>-0.015 0 -0.16 3.14159 1.4708 3.14159</pose>
          <geometry>
            <box>
              <size>0.32 0.0455 0.054</size>
            </box>
          </geometry>
          <surface>
            <contact>
              <ode>
                <kp>1e+06</kp>
                <kd>100</kd>
              </ode>
            </contact>
            <friction>
              <ode>
                <mu>0.2</mu>
                <mu2>0.2</mu2>
              </ode>
              <torsional>
                <ode/>
              </torsional>
            </friction>
            <bounce/>
          </surface>
          <max_contacts>10</max_contacts>
        </collision>
        <collision name='RH_thigh_collision_1'>
          <pose>0 0.008 0 1.5708 -0 0</pose>
          <geometry>
            <cylinder>
              <length>0.08</length>
              <radius>0.044</radius>
            </cylinder>
          </geometry>
          <surface>
            <contact>
              <ode>
                <kp>1e+06</kp>
                <kd>100</kd>
              </ode>
            </contact>
            <friction>
              <ode>
                <mu>0.2</mu>
                <mu2>0.2</mu2>
              </ode>
              <torsional>
                <ode/>
              </torsional>
            </friction>
            <bounce/>
          </surface>
          <max_contacts>10</max_contacts>
        </collision>
        <visual name='RH_thigh_visual'>
          <pose>0 0 0 0 -0 0</pose>
          <geometry>
            <mesh>
              <scale>1 1 1</scale>
              <uri>/home/sujhao/leg_ws/src/legged_control/legged_examples/legged_unitree/legged_unitree_description/meshes/b2w/thigh_mirror.dae</uri>
            </mesh>
          </geometry>
          <material>
            <script>
              <name>Gazebo/DarkGrey</name>
              <uri>file://media/materials/scripts/gazebo.material</uri>
            </script>
          </material>
        </visual>
        <self_collide>0</self_collide>
        <enable_wind>0</enable_wind>
        <kinematic>0</kinematic>
      </link>
      <joint name='RH_KFE' type='revolute'>
        <pose relative_to='RH_thigh'>0 0 -0.32 0 -0 0</pose>
        <parent>RH_thigh</parent>
        <child>RH_calf</child>
        <axis>
          <xyz>0 1 0</xyz>
          <limit>
            <lower>-2.82</lower>
            <upper>-0.43</upper>
            <effort>320</effort>
            <velocity>14</velocity>
          </limit>
          <dynamics>
            <damping>0.2</damping>
            <friction>0</friction>
            <spring_reference>0</spring_reference>
            <spring_stiffness>0</spring_stiffness>
          </dynamics>
        </axis>
      </joint>
      <link name='RH_calf'>
        <pose relative_to='RH_KFE'>0 0 0 0 -0 0</pose>
        <inertial>
          <pose>0.006095 0.012046 -0.29122 0 -0 0</pose>
          <mass>0.151</mass>
          <inertia>
            <ixx>0.028133</ixx>
            <ixy>0.00016307</ixy>
            <ixz>-0.0010034</ixz>
            <iyy>0.029251</iyy>
            <iyz>0.0014765</iyz>
            <izz>0.0028379</izz>
          </inertia>
        </inertial>
        <collision name='RH_calf_collision'>
          <pose>0 0 -0.175 3.14159 1.57079 3.14159</pose>
          <geometry>
            <box>
              <size>0.35 0.04 0.05</size>
            </box>
          </geometry>
          <surface>
            <contact>
              <ode/>
            </contact>
            <friction>
              <ode>
                <mu>0.6</mu>
                <mu2>0.6</mu2>
              </ode>
              <torsional>
                <ode/>
              </torsional>
            </friction>
            <bounce/>
          </surface>
          <max_contacts>10</max_contacts>
        </collision>
        <visual name='RH_calf_visual'>
          <pose>0 0 0 0 -0 0</pose>
          <geometry>
            <mesh>
              <scale>1 1 1</scale>
              <uri>/home/sujhao/leg_ws/src/legged_control/legged_examples/legged_unitree/legged_unitree_description/meshes/b2w/calf_mirror.dae</uri>
            </mesh>
          </geometry>
        </visual>
        <self_collide>1</self_collide>
        <enable_wind>0</enable_wind>
        <kinematic>0</kinematic>
      </link>
      <joint name='RH_foot' type='revolute'>
        <pose relative_to='RH_calf'>0 0 -0.35 0 -0 0</pose>
        <parent>RH_calf</parent>
        <child>RH_FOOT</child>
        <axis>
          <xyz>0 1 0</xyz>
          <limit>
            <effort>20</effort>
            <velocity>50</velocity>
            <lower>-1e+16</lower>
            <upper>1e+16</upper>
          </limit>
          <dynamics>
            <damping>0.5</damping>
            <friction>0.1</friction>
            <spring_reference>0</spring_reference>
            <spring_stiffness>0</spring_stiffness>
          </dynamics>
        </axis>
        <physics>
          <ode>
            <limit>
              <cfm>0</cfm>
              <erp>0.2</erp>
            </limit>
          </ode>
        </physics>
      </joint>
      <link name='RH_FOOT'>
        <pose relative_to='RH_foot'>0 0 0 0 -0 0</pose>
        <inertial>
          <pose>0 -0.051053 0 0 -0 0</pose>
          <mass>0.118</mass>
          <inertia>
            <ixx>0.004121</ixx>
            <ixy>6e-06</ixy>
            <ixz>-4.8e-05</ixz>
            <iyy>0.007776</iyy>
            <iyz>7e-06</iyz>
            <izz>0.004108</izz>
          </inertia>
        </inertial>
        <collision name='RH_FOOT_collision'>
          <pose>0 0 0 0 -0 0</pose>
          <geometry>
            <sphere>
              <radius>0.1</radius>
            </sphere>
          </geometry>
          <surface>
            <contact>
              <ode>
                <kp>1e+06</kp>
                <kd>100</kd>
              </ode>
            </contact>
            <friction>
              <ode>
                <mu>1</mu>
                <mu2>1</mu2>
              </ode>
              <torsional>
                <ode/>
              </torsional>
            </friction>
            <bounce/>
          </surface>
          <max_contacts>10</max_contacts>
        </collision>
        <visual name='RH_FOOT_visual'>
          <pose>0 -0.051053 0 0 -0 0</pose>
          <geometry>
            <mesh>
              <scale>1 1 1</scale>
              <uri>/home/sujhao/leg_ws/src/legged_control/legged_examples/legged_unitree/legged_unitree_description/meshes/b2w/foot_mirror.dae</uri>
            </mesh>
          </geometry>
          <material>
            <script>
              <name>Gazebo/DarkGrey</name>
              <uri>file://media/materials/scripts/gazebo.material</uri>
            </script>
          </material>
        </visual>
        <self_collide>1</self_collide>
        <enable_wind>0</enable_wind>
        <kinematic>0</kinematic>
      </link>
      <joint name='base_imu_joint' type='revolute'>
        <pose relative_to='base'>0 0 0 0 -0 0</pose>
        <parent>base</parent>
        <child>base_imu</child>
        <axis>
          <limit>
            <lower>0</lower>
            <upper>0</upper>
          </limit>
          <dynamics>
            <damping>0</damping>
            <friction>0</friction>
            <spring_reference>0</spring_reference>
            <spring_stiffness>0</spring_stiffness>
          </dynamics>
          <xyz>0 0 1</xyz>
        </axis>
        <physics>
          <ode>
            <limit>
              <cfm>0</cfm>
              <erp>0.2</erp>
            </limit>
          </ode>
        </physics>
      </joint>
      <link name='base_imu'>
        <pose relative_to='base_imu_joint'>0 0 0 0 -0 0</pose>
        <inertial>
          <pose>0 0 0 0 -0 0</pose>
          <mass>0.01</mass>
          <inertia>
            <ixx>1e-06</ixx>
            <ixy>0</ixy>
            <ixz>0</ixz>
            <iyy>1e-06</iyy>
            <iyz>0</iyz>
            <izz>1e-06</izz>
          </inertia>
        </inertial>
        <visual name='base_imu_visual'>
          <pose>0 0 0 0 -0 0</pose>
          <geometry>
            <box>
              <size>0.015 0.015 0.004</size>
            </box>
          </geometry>
          <material>
            <script>
              <name>Gazebo/Orange</name>
              <uri>file://media/materials/scripts/gazebo.material</uri>
            </script>
          </material>
        </visual>
        <self_collide>0</self_collide>
        <enable_wind>0</enable_wind>
        <kinematic>0</kinematic>
      </link>
      <joint name='laser_link_joint' type='revolute'>
        <pose relative_to='base'>0.3 0 0.2 0 -0 0</pose>
        <parent>base</parent>
        <child>laser_link</child>
        <axis>
          <limit>
            <lower>0</lower>
            <upper>0</upper>
          </limit>
          <dynamics>
            <damping>0</damping>
            <friction>0</friction>
            <spring_reference>0</spring_reference>
            <spring_stiffness>0</spring_stiffness>
          </dynamics>
          <xyz>0 0 1</xyz>
        </axis>
        <physics>
          <ode>
            <limit>
              <cfm>0</cfm>
              <erp>0.2</erp>
            </limit>
          </ode>
        </physics>
      </joint>
      <link name='laser_link'>
        <pose relative_to='laser_link_joint'>0 0 0 0 -0 0</pose>
        <inertial>
          <pose>0 0 0 0 -0 0</pose>
          <mass>0.1</mass>
          <inertia>
            <ixx>0.01</ixx>
            <ixy>0</ixy>
            <ixz>0</ixz>
            <iyy>0.01</iyy>
            <iyz>0</iyz>
            <izz>0.01</izz>
          </inertia>
        </inertial>
        <collision name='laser_link_collision'>
          <pose>0 0 0 0 -0 0</pose>
          <geometry>
            <cylinder>
              <length>0.05</length>
              <radius>0.05</radius>
            </cylinder>
          </geometry>
          <surface>
            <contact>
              <ode/>
            </contact>
            <friction>
              <ode/>
              <torsional>
                <ode/>
              </torsional>
            </friction>
            <bounce/>
          </surface>
          <max_contacts>10</max_contacts>
        </collision>
        <visual name='laser_link_visual'>
          <pose>0 0 0 0 -0 0</pose>
          <geometry>
            <cylinder>
              <length>0.05</length>
              <radius>0.05</radius>
            </cylinder>
          </geometry>
          <material>
            <script>
              <name>Gazebo/Orange</name>
              <uri>file://media/materials/scripts/gazebo.material</uri>
            </script>
          </material>
        </visual>
        <sensor name='rplidar' type='ray'>
          <pose>0 0 0 0 -0 0</pose>
          <visualize>0</visualize>
          <update_rate>300</update_rate>
          <ray>
            <scan>
              <horizontal>
                <samples>720</samples>
                <resolution>1</resolution>
                <min_angle>-3</min_angle>
                <max_angle>3</max_angle>
              </horizontal>
              <vertical>
                <samples>1</samples>
                <min_angle>0</min_angle>
                <max_angle>0</max_angle>
              </vertical>
            </scan>
            <range>
              <min>0.1</min>
              <max>100</max>
              <resolution>0.001</resolution>
            </range>
            <noise>
              <type>gaussian</type>
              <mean>0</mean>
              <stddev>0.01</stddev>
            </noise>
          </ray>
          <plugin name='gazebo_rplidar' filename='libgazebo_ros_laser.so'>
            <topicName>/scan</topicName>
            <frameName>laser_link</frameName>
            <robotNamespace>/</robotNamespace>
          </plugin>
        </sensor>
        <self_collide>0</self_collide>
        <enable_wind>0</enable_wind>
        <kinematic>0</kinematic>
      </link>
      <plugin name='gazebo_ros_control' filename='liblegged_hw_sim.so'>
        <robotNamespace>/</robotNamespace>
        <robotParam>legged_robot_description</robotParam>
        <robotSimType>legged_gazebo/LeggedHWSim</robotSimType>
      </plugin>
      <plugin name='skid_steer_drive_controller' filename='libgazebo_ros_skid_steer_drive.so'>
        <robotNamespace>/zrobo</robotNamespace>
        <leftFrontJoint>LF_foot</leftFrontJoint>
        <rightFrontJoint>RF_foot</rightFrontJoint>
        <leftRearJoint>LH_foot</leftRearJoint>
        <rightRearJoint>RH_foot</rightRearJoint>
        <wheelSeparation>0.4</wheelSeparation>
        <wheelDiameter>0.225</wheelDiameter>
        <robotBaseFrame>base</robotBaseFrame>
        <odometryFrame>odom1</odometryFrame>
        <odometryTopic>odom1</odometryTopic>
        <commandTopic>cmd_vel</commandTopic>
        <torque>60</torque>
        <updateRate>100</updateRate>
        <publishWheelTF>1</publishWheelTF>
        <publishTF>1</publishTF>
        <publishWheelJointState>0</publishWheelJointState>
        <alwaysOn>1</alwaysOn>
        <legacyMode>1</legacyMode>
        <broadcastTF>0</broadcastTF>
      </plugin>
      <plugin name='p3d_base_controller' filename='libgazebo_ros_p3d.so'>
        <alwaysOn>1</alwaysOn>
        <updateRate>1000.0</updateRate>
        <bodyName>base</bodyName>
        <topicName>ground_truth/state</topicName>
        <gaussianNoise>0</gaussianNoise>
        <frameName>world</frameName>
        <xyzOffsets>0 0 0</xyzOffsets>
        <rpyOffsets>0 0 0</rpyOffsets>
        <robotNamespace>/</robotNamespace>
      </plugin>
      <pose>0 0 0.78 0 -0 0</pose>
    </model>
    <model name='frc2016_field'>
      <static>1</static>
      <link name='walls'>
        <visual name='walls_visual'>
          <geometry>
            <mesh>
              <uri>model://frc2016_field/meshes/walls.dae</uri>
            </mesh>
          </geometry>
        </visual>
        <collision name='front_turret'>
          <geometry>
            <mesh>
              <uri>model://frc2016_field/meshes/turret_collide.dae</uri>
            </mesh>
          </geometry>
          <max_contacts>10</max_contacts>
          <surface>
            <contact>
              <ode/>
            </contact>
            <bounce/>
            <friction>
              <torsional>
                <ode/>
              </torsional>
              <ode/>
            </friction>
          </surface>
        </collision>
        <collision name='back_turret'>
          <pose>0 0 0 0 -0 3.1415</pose>
          <geometry>
            <mesh>
              <uri>model://frc2016_field/meshes/turret_collide.dae</uri>
            </mesh>
          </geometry>
          <max_contacts>10</max_contacts>
          <surface>
            <contact>
              <ode/>
            </contact>
            <bounce/>
            <friction>
              <torsional>
                <ode/>
              </torsional>
              <ode/>
            </friction>
          </surface>
        </collision>
        <collision name='left_wall'>
          <pose>4.09997 0 0.2413 0 -0 0</pose>
          <geometry>
            <box>
              <size>0.1 16.4592 0.4826</size>
            </box>
          </geometry>
          <max_contacts>10</max_contacts>
          <surface>
            <contact>
              <ode/>
            </contact>
            <bounce/>
            <friction>
              <torsional>
                <ode/>
              </torsional>
              <ode/>
            </friction>
          </surface>
        </collision>
        <collision name='right_wall'>
          <pose>-4.09997 0 0.2413 0 -0 0</pose>
          <geometry>
            <box>
              <size>0.1 16.4592 0.4826</size>
            </box>
          </geometry>
          <max_contacts>10</max_contacts>
          <surface>
            <contact>
              <ode/>
            </contact>
            <bounce/>
            <friction>
              <torsional>
                <ode/>
              </torsional>
              <ode/>
            </friction>
          </surface>
        </collision>
        <collision name='front_solid_wall'>
          <pose>-2.2105 8.2196 1 0 -0 0</pose>
          <geometry>
            <box>
              <size>3.8 0.1 2</size>
            </box>
          </geometry>
          <max_contacts>10</max_contacts>
          <surface>
            <contact>
              <ode/>
            </contact>
            <bounce/>
            <friction>
              <torsional>
                <ode/>
              </torsional>
              <ode/>
            </friction>
          </surface>
        </collision>
        <collision name='back_solid_wall'>
          <pose>2.2105 -8.2196 1 0 -0 0</pose>
          <geometry>
            <box>
              <size>3.8 0.1 2</size>
            </box>
          </geometry>
          <max_contacts>10</max_contacts>
          <surface>
            <contact>
              <ode/>
            </contact>
            <bounce/>
            <friction>
              <torsional>
                <ode/>
              </torsional>
              <ode/>
            </friction>
          </surface>
        </collision>
        <collision name='front_partial_wall'>
          <pose>1.85 8.2196 1 0 -0 0</pose>
          <geometry>
            <box>
              <size>2.1 0.1 2</size>
            </box>
          </geometry>
          <max_contacts>10</max_contacts>
          <surface>
            <contact>
              <ode/>
            </contact>
            <bounce/>
            <friction>
              <torsional>
                <ode/>
              </torsional>
              <ode/>
            </friction>
          </surface>
        </collision>
        <collision name='front_partial_wall_mid'>
          <pose>3.4 8.2196 0.86 0 -0 0</pose>
          <geometry>
            <box>
              <size>1.25 0.1 1.12</size>
            </box>
          </geometry>
          <max_contacts>10</max_contacts>
          <surface>
            <contact>
              <ode/>
            </contact>
            <bounce/>
            <friction>
              <torsional>
                <ode/>
              </torsional>
              <ode/>
            </friction>
          </surface>
        </collision>
        <collision name='front_partial_wall_lower_left'>
          <pose>3.36 8.2196 0.25 0 -0 0</pose>
          <geometry>
            <box>
              <size>0.3 0.1 0.5</size>
            </box>
          </geometry>
          <max_contacts>10</max_contacts>
          <surface>
            <contact>
              <ode/>
            </contact>
            <bounce/>
            <friction>
              <torsional>
                <ode/>
              </torsional>
              <ode/>
            </friction>
          </surface>
        </collision>
        <collision name='front_partial_wall_lower_right'>
          <pose>4 8.2196 0.25 0 -0 0</pose>
          <geometry>
            <box>
              <size>0.3 0.1 0.5</size>
            </box>
          </geometry>
          <max_contacts>10</max_contacts>
          <surface>
            <contact>
              <ode/>
            </contact>
            <bounce/>
            <friction>
              <torsional>
                <ode/>
              </torsional>
              <ode/>
            </friction>
          </surface>
        </collision>
        <collision name='front_partial_wall_upper_right'>
          <pose>3.76 8.2196 1.7 0 -0 0</pose>
          <geometry>
            <box>
              <size>0.54 0.1 0.6</size>
            </box>
          </geometry>
          <max_contacts>10</max_contacts>
          <surface>
            <contact>
              <ode/>
            </contact>
            <bounce/>
            <friction>
              <torsional>
                <ode/>
              </torsional>
              <ode/>
            </friction>
          </surface>
        </collision>
        <collision name='front_partial_wall_upper_left'>
          <pose>2.95 8.2196 1.7 0 -0 0</pose>
          <geometry>
            <box>
              <size>0.54 0.1 0.6</size>
            </box>
          </geometry>
          <max_contacts>10</max_contacts>
          <surface>
            <contact>
              <ode/>
            </contact>
            <bounce/>
            <friction>
              <torsional>
                <ode/>
              </torsional>
              <ode/>
            </friction>
          </surface>
        </collision>
        <collision name='front_partial_wall_upper_mid'>
          <pose>3.36 8.2196 1.84 0 -0 0</pose>
          <geometry>
            <box>
              <size>0.3 0.1 0.3</size>
            </box>
          </geometry>
          <max_contacts>10</max_contacts>
          <surface>
            <contact>
              <ode/>
            </contact>
            <bounce/>
            <friction>
              <torsional>
                <ode/>
              </torsional>
              <ode/>
            </friction>
          </surface>
        </collision>
        <collision name='back_partial_wall'>
          <pose>-1.85 -8.2196 1 0 -0 0</pose>
          <geometry>
            <box>
              <size>2.1 0.1 2</size>
            </box>
          </geometry>
          <max_contacts>10</max_contacts>
          <surface>
            <contact>
              <ode/>
            </contact>
            <bounce/>
            <friction>
              <torsional>
                <ode/>
              </torsional>
              <ode/>
            </friction>
          </surface>
        </collision>
        <collision name='back_partial_wall_mid'>
          <pose>-3.4 -8.2196 0.86 0 -0 0</pose>
          <geometry>
            <box>
              <size>1.25 0.1 1.12</size>
            </box>
          </geometry>
          <max_contacts>10</max_contacts>
          <surface>
            <contact>
              <ode/>
            </contact>
            <bounce/>
            <friction>
              <torsional>
                <ode/>
              </torsional>
              <ode/>
            </friction>
          </surface>
        </collision>
        <collision name='back_partial_wall_lower_left'>
          <pose>-3.36 -8.2196 0.25 0 -0 0</pose>
          <geometry>
            <box>
              <size>0.3 0.1 0.5</size>
            </box>
          </geometry>
          <max_contacts>10</max_contacts>
          <surface>
            <contact>
              <ode/>
            </contact>
            <bounce/>
            <friction>
              <torsional>
                <ode/>
              </torsional>
              <ode/>
            </friction>
          </surface>
        </collision>
        <collision name='back_partial_wall_lower_right'>
          <pose>-4 -8.2196 0.25 0 -0 0</pose>
          <geometry>
            <box>
              <size>0.3 0.1 0.5</size>
            </box>
          </geometry>
          <max_contacts>10</max_contacts>
          <surface>
            <contact>
              <ode/>
            </contact>
            <bounce/>
            <friction>
              <torsional>
                <ode/>
              </torsional>
              <ode/>
            </friction>
          </surface>
        </collision>
        <collision name='back_partial_wall_upper_right'>
          <pose>-3.76 -8.2196 1.7 0 -0 0</pose>
          <geometry>
            <box>
              <size>0.54 0.1 0.6</size>
            </box>
          </geometry>
          <max_contacts>10</max_contacts>
          <surface>
            <contact>
              <ode/>
            </contact>
            <bounce/>
            <friction>
              <torsional>
                <ode/>
              </torsional>
              <ode/>
            </friction>
          </surface>
        </collision>
        <collision name='back_partial_wall_upper_left'>
          <pose>-2.95 -8.2196 1.7 0 -0 0</pose>
          <geometry>
            <box>
              <size>0.54 0.1 0.6</size>
            </box>
          </geometry>
          <max_contacts>10</max_contacts>
          <surface>
            <contact>
              <ode/>
            </contact>
            <bounce/>
            <friction>
              <torsional>
                <ode/>
              </torsional>
              <ode/>
            </friction>
          </surface>
        </collision>
        <collision name='back_partial_wall_upper_mid'>
          <pose>-3.36 -8.2196 1.84 0 -0 0</pose>
          <geometry>
            <box>
              <size>0.3 0.1 0.3</size>
            </box>
          </geometry>
          <max_contacts>10</max_contacts>
          <surface>
            <contact>
              <ode/>
            </contact>
            <bounce/>
            <friction>
              <torsional>
                <ode/>
              </torsional>
              <ode/>
            </friction>
          </surface>
        </collision>
        <visual name='blue_passage_border_long'>
          <pose>2.72665 4.5882 0.0127 0 -0 0</pose>
          <geometry>
            <box>
              <size>0.0762 7.3025 0.0254</size>
            </box>
          </geometry>
          <material>
            <ambient>0 0 1 1</ambient>
            <diffuse>0 0 1 1</diffuse>
          </material>
        </visual>
        <collision name='blue_passage_border_long'>
          <pose>2.72665 4.5882 0.0127 0 -0 0</pose>
          <geometry>
            <box>
              <size>0.0762 7.3025 0.0254</size>
            </box>
          </geometry>
          <max_contacts>10</max_contacts>
          <surface>
            <contact>
              <ode/>
            </contact>
            <bounce/>
            <friction>
              <torsional>
                <ode/>
              </torsional>
              <ode/>
            </friction>
          </surface>
        </collision>
        <visual name='blue_passage_border_short'>
          <pose>3.37435 0.97352 0.0127 0 -0 0</pose>
          <geometry>
            <box>
              <size>1.37165 0.0762 0.0254</size>
            </box>
          </geometry>
          <material>
            <ambient>0 0 1 1</ambient>
            <diffuse>0 0 1 1</diffuse>
          </material>
        </visual>
        <collision name='blue_passage_border_short'>
          <pose>3.37435 0.97352 0.0127 0 -0 0</pose>
          <geometry>
            <box>
              <size>1.37165 0.0762 0.0254</size>
            </box>
          </geometry>
          <max_contacts>10</max_contacts>
          <surface>
            <contact>
              <ode/>
            </contact>
            <bounce/>
            <friction>
              <torsional>
                <ode/>
              </torsional>
              <ode/>
            </friction>
          </surface>
        </collision>
        <visual name='blue_divider_1'>
          <pose>2.63052 2.80648 0.31114 0 -0 0</pose>
          <geometry>
            <box>
              <size>0.009525 1.2192 0.6096</size>
            </box>
          </geometry>
        </visual>
        <collision name='blue_divider_1'>
          <pose>2.63052 2.80648 0.31114 0 -0 0</pose>
          <geometry>
            <box>
              <size>0.009525 1.2192 0.6096</size>
            </box>
          </geometry>
          <max_contacts>10</max_contacts>
          <surface>
            <contact>
              <ode/>
            </contact>
            <bounce/>
            <friction>
              <torsional>
                <ode/>
              </torsional>
              <ode/>
            </friction>
          </surface>
        </collision>
        <visual name='blue_divider_2'>
          <pose>1.28432 2.80648 0.31114 0 -0 0</pose>
          <geometry>
            <box>
              <size>0.009525 1.2192 0.6096</size>
            </box>
          </geometry>
        </visual>
        <collision name='blue_divider_2'>
          <pose>1.28432 2.80648 0.31114 0 -0 0</pose>
          <geometry>
            <box>
              <size>0.009525 1.2192 0.6096</size>
            </box>
          </geometry>
          <max_contacts>10</max_contacts>
          <surface>
            <contact>
              <ode/>
            </contact>
            <bounce/>
            <friction>
              <torsional>
                <ode/>
              </torsional>
              <ode/>
            </friction>
          </surface>
        </collision>
        <visual name='blue_divider_3'>
          <pose>-0.06189 2.80648 0.31114 0 -0 0</pose>
          <geometry>
            <box>
              <size>0.009525 1.2192 0.6096</size>
            </box>
          </geometry>
        </visual>
        <collision name='blue_divider_3'>
          <pose>-0.06189 2.80648 0.31114 0 -0 0</pose>
          <geometry>
            <box>
              <size>0.009525 1.2192 0.6096</size>
            </box>
          </geometry>
          <max_contacts>10</max_contacts>
          <surface>
            <contact>
              <ode/>
            </contact>
            <bounce/>
            <friction>
              <torsional>
                <ode/>
              </torsional>
              <ode/>
            </friction>
          </surface>
        </collision>
        <visual name='blue_divider_4'>
          <pose>-1.40809 2.80648 0.31114 0 -0 0</pose>
          <geometry>
            <box>
              <size>0.009525 1.2192 0.6096</size>
            </box>
          </geometry>
        </visual>
        <collision name='blue_divider_4'>
          <pose>-1.40809 2.80648 0.31114 0 -0 0</pose>
          <geometry>
            <box>
              <size>0.009525 1.2192 0.6096</size>
            </box>
          </geometry>
          <max_contacts>10</max_contacts>
          <surface>
            <contact>
              <ode/>
            </contact>
            <bounce/>
            <friction>
              <torsional>
                <ode/>
              </torsional>
              <ode/>
            </friction>
          </surface>
        </collision>
        <visual name='blue_divider_5'>
          <pose>-2.75428 2.80648 0.31114 0 -0 0</pose>
          <geometry>
            <box>
              <size>0.009525 1.2192 0.6096</size>
            </box>
          </geometry>
        </visual>
        <collision name='blue_divider_5'>
          <pose>-2.75428 2.80648 0.31114 0 -0 0</pose>
          <geometry>
            <box>
              <size>0.009525 1.2192 0.6096</size>
            </box>
          </geometry>
          <max_contacts>10</max_contacts>
          <surface>
            <contact>
              <ode/>
            </contact>
            <bounce/>
            <friction>
              <torsional>
                <ode/>
              </torsional>
              <ode/>
            </friction>
          </surface>
        </collision>
        <visual name='blue_barrier_ramp_up'>
          <pose>-0.7334 3.22301 0.05063 -0.248866 0 0</pose>
          <geometry>
            <box>
              <size>6.71817 0.3048 0.00635</size>
            </box>
          </geometry>
        </visual>
        <collision name='blue_barrier_ramp_up'>
          <pose>-0.7334 3.22301 0.05063 -0.248866 0 0</pose>
          <geometry>
            <box>
              <size>6.71817 0.3048 0.00635</size>
            </box>
          </geometry>
          <max_contacts>10</max_contacts>
          <surface>
            <contact>
              <ode/>
            </contact>
            <bounce/>
            <friction>
              <torsional>
                <ode/>
              </torsional>
              <ode/>
            </friction>
          </surface>
        </collision>
        <visual name='blue_barrier_ramp_down'>
          <pose>-0.7334 2.31802 0.05063 0.248866 -0 0</pose>
          <geometry>
            <box>
              <size>6.71817 0.3048 0.00635</size>
            </box>
          </geometry>
        </visual>
        <collision name='blue_barrier_ramp_down'>
          <pose>-0.7334 2.31802 0.05063 0.248866 -0 0</pose>
          <geometry>
            <box>
              <size>6.71817 0.3048 0.00635</size>
            </box>
          </geometry>
          <max_contacts>10</max_contacts>
          <surface>
            <contact>
              <ode/>
            </contact>
            <bounce/>
            <friction>
              <torsional>
                <ode/>
              </torsional>
              <ode/>
            </friction>
          </surface>
        </collision>
        <visual name='red_passage_border_long'>
          <pose>-2.7273 -4.58839 0.0127 0 -0 0</pose>
          <geometry>
            <box>
              <size>0.0762 7.3025 0.0254</size>
            </box>
          </geometry>
          <material>
            <ambient>1 0 0 1</ambient>
            <diffuse>1 0 0 1</diffuse>
          </material>
        </visual>
        <collision name='red_passage_border_long'>
          <pose>-2.7273 -4.58839 0.0127 0 -0 0</pose>
          <geometry>
            <box>
              <size>0.0762 7.3025 0.0254</size>
            </box>
          </geometry>
          <max_contacts>10</max_contacts>
          <surface>
            <contact>
              <ode/>
            </contact>
            <bounce/>
            <friction>
              <torsional>
                <ode/>
              </torsional>
              <ode/>
            </friction>
          </surface>
        </collision>
        <visual name='red_passage_border_short'>
          <pose>-3.375 -0.97372 0.0127 0 -0 0</pose>
          <geometry>
            <box>
              <size>1.37165 0.0762 0.0254</size>
            </box>
          </geometry>
          <material>
            <ambient>1 0 0 1</ambient>
            <diffuse>1 0 0 1</diffuse>
          </material>
        </visual>
        <collision name='red_passage_border_short'>
          <pose>-3.375 -0.97372 0.0127 0 -0 0</pose>
          <geometry>
            <box>
              <size>1.37165 0.0762 0.0254</size>
            </box>
          </geometry>
          <max_contacts>10</max_contacts>
          <surface>
            <contact>
              <ode/>
            </contact>
            <bounce/>
            <friction>
              <torsional>
                <ode/>
              </torsional>
              <ode/>
            </friction>
          </surface>
        </collision>
        <visual name='red_divider_1'>
          <pose>-2.63117 -2.76442 0.31114 0 -0 0</pose>
          <geometry>
            <box>
              <size>0.009525 1.2192 0.6096</size>
            </box>
          </geometry>
        </visual>
        <collision name='red_divider_1'>
          <pose>-2.63117 -2.72845 0.31114 0 -0 0</pose>
          <geometry>
            <box>
              <size>0.009525 1.2192 0.6096</size>
            </box>
          </geometry>
          <max_contacts>10</max_contacts>
          <surface>
            <contact>
              <ode/>
            </contact>
            <bounce/>
            <friction>
              <torsional>
                <ode/>
              </torsional>
              <ode/>
            </friction>
          </surface>
        </collision>
        <visual name='red_divider_2'>
          <pose>-1.28496 -2.76442 0.31114 0 -0 0</pose>
          <geometry>
            <box>
              <size>0.009525 1.2192 0.6096</size>
            </box>
          </geometry>
        </visual>
        <collision name='red_divider_2'>
          <pose>-1.28496 -2.76442 0.31114 0 -0 0</pose>
          <geometry>
            <box>
              <size>0.009525 1.2192 0.6096</size>
            </box>
          </geometry>
          <max_contacts>10</max_contacts>
          <surface>
            <contact>
              <ode/>
            </contact>
            <bounce/>
            <friction>
              <torsional>
                <ode/>
              </torsional>
              <ode/>
            </friction>
          </surface>
        </collision>
        <visual name='red_divider_3'>
          <pose>0.06124 -2.76442 0.31114 0 -0 0</pose>
          <geometry>
            <box>
              <size>0.009525 1.2192 0.6096</size>
            </box>
          </geometry>
        </visual>
        <collision name='red_divider_3'>
          <pose>0.06124 -2.76442 0.31114 0 -0 0</pose>
          <geometry>
            <box>
              <size>0.009525 1.2192 0.6096</size>
            </box>
          </geometry>
          <max_contacts>10</max_contacts>
          <surface>
            <contact>
              <ode/>
            </contact>
            <bounce/>
            <friction>
              <torsional>
                <ode/>
              </torsional>
              <ode/>
            </friction>
          </surface>
        </collision>
        <visual name='red_divider_4'>
          <pose>1.40744 -2.76442 0.31114 0 -0 0</pose>
          <geometry>
            <box>
              <size>0.009525 1.2192 0.6096</size>
            </box>
          </geometry>
        </visual>
        <collision name='red_divider_4'>
          <pose>1.40744 -2.76442 0.31114 0 -0 0</pose>
          <geometry>
            <box>
              <size>0.009525 1.2192 0.6096</size>
            </box>
          </geometry>
          <max_contacts>10</max_contacts>
          <surface>
            <contact>
              <ode/>
            </contact>
            <bounce/>
            <friction>
              <torsional>
                <ode/>
              </torsional>
              <ode/>
            </friction>
          </surface>
        </collision>
        <visual name='red_divider_5'>
          <pose>2.75363 -2.76442 0.31114 0 -0 0</pose>
          <geometry>
            <box>
              <size>0.009525 1.2192 0.6096</size>
            </box>
          </geometry>
        </visual>
        <collision name='red_divider_5'>
          <pose>2.75363 -2.76442 0.31114 0 -0 0</pose>
          <geometry>
            <box>
              <size>0.009525 1.2192 0.6096</size>
            </box>
          </geometry>
          <max_contacts>10</max_contacts>
          <surface>
            <contact>
              <ode/>
            </contact>
            <bounce/>
            <friction>
              <torsional>
                <ode/>
              </torsional>
              <ode/>
            </friction>
          </surface>
        </collision>
        <visual name='red_barrier_ramp_down'>
          <pose>0.73275 -2.31261 0.05063 -0.248866 0 0</pose>
          <geometry>
            <box>
              <size>6.71817 0.3048 0.00635</size>
            </box>
          </geometry>
        </visual>
        <collision name='red_barrier_ramp_down'>
          <pose>0.73275 -2.31261 0.05063 -0.248866 0 0</pose>
          <geometry>
            <box>
              <size>6.71817 0.3048 0.00635</size>
            </box>
          </geometry>
          <max_contacts>10</max_contacts>
          <surface>
            <contact>
              <ode/>
            </contact>
            <bounce/>
            <friction>
              <torsional>
                <ode/>
              </torsional>
              <ode/>
            </friction>
          </surface>
        </collision>
        <visual name='red_barrier_ramp_up'>
          <pose>0.73275 -3.21691 0.05063 0.248866 -0 0</pose>
          <geometry>
            <box>
              <size>6.71817 0.3048 0.00635</size>
            </box>
          </geometry>
        </visual>
        <collision name='red_barrier_ramp_up'>
          <pose>0.73275 -3.21691 0.05063 0.248866 -0 0</pose>
          <geometry>
            <box>
              <size>6.71817 0.3048 0.00635</size>
            </box>
          </geometry>
          <max_contacts>10</max_contacts>
          <surface>
            <contact>
              <ode/>
            </contact>
            <bounce/>
            <friction>
              <torsional>
                <ode/>
              </torsional>
              <ode/>
            </friction>
          </surface>
        </collision>
        <self_collide>0</self_collide>
        <enable_wind>0</enable_wind>
        <kinematic>0</kinematic>
      </link>
      <pose>-0.23368 -0.252589 0 0 -0 0</pose>
    </model>
    <state world_name='default'>
      <sim_time>137 306000000</sim_time>
      <real_time>140 707619029</real_time>
      <wall_time>1748298081 252276719</wall_time>
      <iterations>137306</iterations>
      <model name='b2w'>
        <pose>0.279058 -4.99624 0.631932 -0.000389 0.007026 -1.60142</pose>
        <scale>1 1 1</scale>
        <link name='LF_FOOT'>
          <pose>0.505296 -5.32654 0.099846 0.090199 -0.400545 -1.63727</pose>
          <velocity>0.002315 -0.004932 -0.075116 0.049273 0.023072 0.073587</velocity>
          <acceleration>-0.096964 0.065575 0.004139 1.06643 -1.54181 2.35519</acceleration>
          <wrench>-0.011442 0.007738 0.000488 0 -0 0</wrench>
        </link>
        <link name='LF_calf'>
          <pose>0.487202 -5.13184 0.390123 0.099701 -0.585374 -1.65722</pose>
          <velocity>-0.005096 -0.019904 -0.064983 0.049033 0.024965 0.072651</velocity>
          <acceleration>-0.125765 0.21786 -0.063841 0.432734 -1.45677 0.149943</acceleration>
          <wrench>-0.018991 0.032897 -0.00964 0 -0 0</wrench>
        </link>
        <link name='LF_hip'>
          <pose>0.340966 -5.32678 0.629596 0.083061 0.007026 -1.60143</pose>
          <velocity>0.013188 0.011791 -0.027962 0.057496 0.024694 0.073493</velocity>
          <acceleration>-0.489451 -0.115592 -1.12486 -1.02366 -0.459924 1.03305</acceleration>
          <wrench>-0.291223 -0.068777 -0.669294 0 -0 0</wrench>
        </link>
        <link name='LF_thigh'>
          <pose>0.460225 -5.3305 0.639531 0.106048 0.670028 -1.536</pose>
          <velocity>0.013702 0.019824 -0.031278 -0.164931 0.031811 0.055111</velocity>
          <acceleration>-0.450363 -0.135532 -0.931817 -3.04874 -0.566988 -0.113872</acceleration>
          <wrench>-0.399923 -0.120353 -0.827454 0 -0 0</wrench>
        </link>
        <link name='LH_FOOT'>
          <pose>0.513349 -4.67395 0.225184 0.099277 -0.65652 -1.66269</pose>
          <velocity>0.131516 0.146811 -1.79573 -2.9131 -0.152287 0.33326</velocity>
          <acceleration>-0.220435 2.39945 -9.28463 2.38408 -0.526316 -0.518356</acceleration>
          <wrench>-0.026011 0.283135 -1.09559 0 -0 0</wrench>
        </link>
        <link name='LH_calf'>
          <pose>0.503061 -4.41355 0.458824 0.117074 -0.8337 -1.68883</pose>
          <velocity>0.009137 -0.643754 -0.919455 -2.9131 -0.152307 0.333245</velocity>
          <acceleration>-0.115936 0.789345 -8.54029 2.08617 -1.54748 0.01829</acceleration>
          <wrench>-0.017506 0.119191 -1.28958 0 -0 0</wrench>
        </link>
        <link name='LH_hip'>
          <pose>0.361082 -4.67011 0.634213 0.078593 0.007028 -1.60142</pose>
          <velocity>-0.034587 0.013027 0.00921 0.054952 -0.048823 0.071967</velocity>
          <acceleration>0.406238 -0.140217 -1.7206 -2.906 1.35404 3.03844</acceleration>
          <wrench>0.241712 -0.083429 -1.02376 0 -0 0</wrench>
        </link>
        <link name='LH_thigh'>
          <pose>0.480385 -4.67382 0.643612 0.135134 0.948696 -1.49192</pose>
          <velocity>-0.034766 0.021448 0.014674 2.70876 0.064446 -0.21385</velocity>
          <acceleration>0.442025 -1.16155 -2.4751 -0.913598 1.55524 -0.847481</acceleration>
          <wrench>0.392518 -1.03146 -2.19789 0 -0 0</wrench>
        </link>
        <link name='RF_FOOT'>
          <pose>0.037368 -5.32262 0.224817 -0.123505 -0.669391 -1.52386</pose>
          <velocity>-0.139237 0.112098 -1.8016 -2.97256 -0.137114 -0.243942</velocity>
          <acceleration>0.03557 2.91886 -9.2813 1.76894 0.491817 3.0073</acceleration>
          <wrench>0.004197 0.344426 -1.09519 0 -0 0</wrench>
        </link>
        <link name='RF_calf'>
          <pose>0.067479 -5.05963 0.453801 -0.146603 -0.848203 -1.49043</pose>
          <velocity>-0.106452 -0.65308 -0.926579 -2.97256 -0.137134 -0.243954</velocity>
          <acceleration>0.019274 1.16906 -8.44588 2.68735 0.876248 0.191159</acceleration>
          <wrench>0.00291 0.176528 -1.27533 0 -0 0</wrench>
        </link>
        <link name='RF_hip'>
          <pose>0.197034 -5.32237 0.629651 -0.096761 0.007029 -1.60142</pose>
          <velocity>0.012894 0.001379 -0.033696 0.055143 -0.03955 0.072185</velocity>
          <acceleration>-0.481374 0.059102 -0.946817 -1.87258 -0.079702 2.98543</acceleration>
          <wrench>-0.286417 0.035166 -0.563356 0 -0 0</wrench>
        </link>
        <link name='RF_thigh'>
          <pose>0.077917 -5.3188 0.641217 -0.163487 0.93532 -1.73272</pose>
          <velocity>0.012168 -0.007669 -0.038334 2.86181 0.064721 0.409937</velocity>
          <acceleration>-0.445258 -0.707572 -1.69565 0.650545 0.478159 -1.65662</acceleration>
          <wrench>-0.395389 -0.628324 -1.50574 0 -0 0</wrench>
        </link>
        <link name='RH_FOOT'>
          <pose>0.06779 -4.64795 0.099844 -0.060547 -0.394022 -1.57775</pose>
          <velocity>-0.006689 -0.015111 -0.076236 0.151057 -0.06681 0.066082</velocity>
          <acceleration>0.10798 0.45152 0.235909 2.31608 1.55674 -0.931806</acceleration>
          <wrench>0.012742 0.053279 0.027837 0 -0 0</wrench>
        </link>
        <link name='RH_calf'>
          <pose>0.089952 -4.45911 0.393692 -0.066469 -0.570876 -1.56507</pose>
          <velocity>-0.03894 -0.057424 -0.046146 0.15063 -0.068475 0.066915</velocity>
          <acceleration>0.212197 0.571606 0.084379 -2.33783 -0.738758 -2.80257</acceleration>
          <wrench>0.032042 0.086312 0.012741 0 -0 0</wrench>
        </link>
        <link name='RH_hip'>
          <pose>0.21715 -4.6657 0.634269 -0.055919 0.007029 -1.60142</pose>
          <velocity>-0.034942 0.002563 0.003342 0.054386 -0.065586 0.072099</velocity>
          <acceleration>0.414659 0.031386 -1.62986 -1.65359 -0.732995 2.39332</acceleration>
          <wrench>0.246722 0.018675 -0.969768 0 -0 0</wrench>
        </link>
        <link name='RH_thigh'>
          <pose>0.097662 -4.66208 0.640962 -0.072202 0.684494 -1.64672</pose>
          <velocity>-0.035649 -0.006525 -0.004439 -0.202889 -0.057916 0.086382</velocity>
          <acceleration>0.472569 0.32721 -1.41208 1.40292 0.951556 2.5284</acceleration>
          <wrench>0.419641 0.290562 -1.25393 0 -0 0</wrench>
        </link>
        <link name='base'>
          <pose>0.279058 -4.99624 0.631932 -0.000389 0.007026 -1.60142</pose>
          <velocity>-0.010859 0.007202 -0.012248 0.055408 -0.042322 0.072482</velocity>
          <acceleration>-0.036644 -0.047133 -1.37124 -2.47752 -1.34607 2.07361</acceleration>
          <wrench>-0.586296 -0.754126 -21.9398 0 -0 0</wrench>
        </link>
        <link name='base_imu'>
          <pose>0.279058 -4.99624 0.631932 -0.000389 0.007026 -1.60142</pose>
          <velocity>-0.010859 0.007203 -0.012246 0.055425 -0.042343 0.072437</velocity>
          <acceleration>-0.037676 -0.040281 -1.3657 -0.963537 0.975839 -1.50215</acceleration>
          <wrench>-0.000377 -0.000403 -0.013657 0 -0 0</wrench>
        </link>
        <link name='laser_link'>
          <pose>0.269907 -5.2975 0.829819 -0.000389 0.007026 -1.60142</pose>
          <velocity>0.002597 -0.004428 -0.029329 0.055424 -0.042341 0.07244</velocity>
          <acceleration>-0.26679 0.165347 -1.06651 -0.96359 0.975887 -1.49538</acceleration>
          <wrench>-0.026679 0.016535 -0.106651 0 -0 0</wrench>
        </link>
      </model>
      <model name='frc2016_field'>
        <pose>-0.23368 -0.252589 0 0 -0 0</pose>
        <scale>1 1 1</scale>
        <link name='walls'>
          <pose>-0.23368 -0.252589 0 0 -0 0</pose>
          <velocity>0 0 0 0 -0 0</velocity>
          <acceleration>0 0 0 0 -0 0</acceleration>
          <wrench>0 0 0 0 -0 0</wrench>
        </link>
      </model>
      <model name='ground_plane'>
        <pose>0 0 0 0 -0 0</pose>
        <scale>1 1 1</scale>
        <link name='link'>
          <pose>0 0 0 0 -0 0</pose>
          <velocity>0 0 0 0 -0 0</velocity>
          <acceleration>0 0 0 0 -0 0</acceleration>
          <wrench>0 0 0 0 -0 0</wrench>
        </link>
      </model>
      <light name='sun'>
        <pose>0 0 10 0 -0 0</pose>
      </light>
    </state>
    <gui fullscreen='0'>
      <camera name='user_camera'>
        <pose>-22.1411 -3.74358 9.36791 0 0.439643 0.048202</pose>
        <view_controller>orbit</view_controller>
        <projection_type>perspective</projection_type>
      </camera>
    </gui>
  </world>
</sdf>
