<?xml version="1.0" ?>
<!-- =================================================================================== -->
<!-- |    This document was autogenerated by xacro from robot_arm.xacro                | -->
<!-- |    EDITING THIS FILE BY HAND IS NOT RECOMMENDED                                 | -->
<!-- =================================================================================== -->
<robot name="robot">
  <material name="black">
    <color rgba="0.0 0.0 0.0 1.0"/>
  </material>
  <material name="blue">
    <color rgba="0.0 0.0 0.8 1.0"/>
  </material>
  <material name="green">
    <color rgba="0.0 0.8 0.0 1.0"/>
  </material>
  <material name="grey">
    <color rgba="0.2 0.2 0.2 1.0"/>
  </material>
  <material name="silver">
    <color rgba="0.9137254901960784 0.9137254901960784 0.8470588235294118 1.0"/>
  </material>
  <material name="orange">
    <color rgba="1.0 0.4235294117647059 0.0392156862745098 1.0"/>
  </material>
  <material name="brown">
    <color rgba="0.8705882352941177 0.8117647058823529 0.7647058823529411 1.0"/>
  </material>
  <material name="red">
    <color rgba="0.8 0.0 0.0 1.0"/>
  </material>
  <material name="white">
    <color rgba="1.0 1.0 1.0 1.0"/>
  </material>
  <!-- ros_control plugin -->
  <gazebo>
    <plugin filename="liblegged_hw_sim.so" name="gazebo_ros_control">
      <robotNamespace>/</robotNamespace>
      <robotParam>legged_robot_description</robotParam>
      <robotSimType>legged_gazebo/LeggedHWSim</robotSimType>
    </plugin>
  </gazebo>
  <!-- <gazebo>
    <plugin name="gazebo_wheel" filename="libgazebo_ros_control.so">
      <robotNamespace>/zrobo</robotNamespace>
      <robotSimType>gazebo_ros_control/DefaultRobotHWSim</robotSimType>
      <legacyModeNS>true</legacyModeNS>
      <broadcastTF>1</broadcastTF>
      <publishOdomTF>true</publishOdomTF>
      <odometryTopic>odom</odometryTopic>
      <odometryFrame>odom</odometryFrame>

    </plugin>
  </gazebo> -->
  <!--<gazebo>
	    <plugin name="skid_steer_drive_controller" filename="libgazebo_ros_skid_steer_drive.so">
		<updateRate>100.0</updateRate>
		<robotNamespace>/zrobo</robotNamespace>
		<leftFrontJoint>LF_foot</leftFrontJoint>
		<rightFrontJoint>RF_foot</rightFrontJoint>
		<leftRearJoint>LH_foot</leftRearJoint>
		<rightRearJoint>RH_foot</rightRearJoint>
		<wheelSeparation>0.3</wheelSeparation>
		<wheelDiameter>0.225</wheelDiameter>
		<robotBaseFrame>base</robotBaseFrame>
		<torque>60</torque>
		<topicName>cmd_vel</topicName>
		<broadcastTF>false</broadcastTF>
	    </plugin>
	</gazebo> -->
  <gazebo>
    <plugin filename="libgazebo_ros_skid_steer_drive.so" name="skid_steer_drive_controller">
      <robotNamespace>/zrobo</robotNamespace>
      <leftFrontJoint>LF_foot</leftFrontJoint>
      <rightFrontJoint>RF_foot</rightFrontJoint>
      <leftRearJoint>LH_foot</leftRearJoint>
      <rightRearJoint>RH_foot</rightRearJoint>
      <wheelSeparation>0.4</wheelSeparation>
      <wheelDiameter>0.225</wheelDiameter>
      <robotBaseFrame>base</robotBaseFrame>
      <odometryFrame>odom1</odometryFrame>
      <odometryTopic>odom1</odometryTopic>
      <commandTopic>cmd_vel</commandTopic>
      <torque>60</torque>
      <updateRate>100</updateRate>
      <publishWheelTF>true</publishWheelTF>
      <publishTF>true</publishTF>
      <publishWheelJointState>false</publishWheelJointState>
      <alwaysOn>true</alwaysOn>
      <legacyMode>true</legacyMode>
      <broadcastTF>false</broadcastTF>
    </plugin>
  </gazebo>
  <gazebo>
    <plugin filename="libgazebo_ros_p3d.so" name="p3d_base_controller">
      <alwaysOn>true</alwaysOn>
      <updateRate>1000.0</updateRate>
      <bodyName>base</bodyName>
      <topicName>ground_truth/state</topicName>
      <gaussianNoise>0</gaussianNoise>
      <frameName>world</frameName>
      <xyzOffsets>0 0 0</xyzOffsets>
      <rpyOffsets>0 0 0</rpyOffsets>
    </plugin>
  </gazebo>
  <!-- <xacro:property name="stick_mass" value="0.00001"/> -->
  <!-- <xacro:property name="stick_radius" value="0.01"/>
    <xacro:property name="stick_length" value="0.2"/> -->
  <link name="base">
    <visual>
      <origin rpy="0 0 0" xyz="0 0 0"/>
      <geometry>
        <mesh filename="package://legged_unitree_description/meshes/b2w/trunk.dae" scale="1 1 1"/>
      </geometry>
    </visual>
    <collision>
      <origin rpy="0 0 0" xyz="0 0 0"/>
      <geometry>
        <box size="0.5 0.28 0.15"/>
      </geometry>
    </collision>
    <inertial>
      <origin rpy="0 0 0" xyz="-0.000458 0.005261 0.000665"/>
      <mass value="16.0"/>
      <inertia ixx="0.0158533" ixy="-3.66e-05" ixz="-6.11e-05" iyy="0.0377999" iyz="-2.75e-05" izz="0.0456542"/>
    </inertial>
  </link>
  <!-- Imu is fixed to the base link -->
  <joint name="base_imu_joint" type="fixed">
    <origin rpy="0. 0. 0." xyz="0. 0. 0."/>
    <parent link="base"/>
    <child link="base_imu"/>
  </joint>
  <!-- Imu link -->
  <link name="base_imu">
    <inertial>
      <mass value="0.01"/>
      <origin rpy="0 0 0" xyz="0 0 0"/>
      <inertia ixx="0.000001" ixy="0" ixz="0" iyy="0.000001" iyz="0" izz="0.000001"/>
    </inertial>
    <visual>
      <origin rpy="0 0 0" xyz="0 0 0"/>
      <geometry>
        <box size="0.015 0.015 0.004"/>
      </geometry>
    </visual>
    <material name="orange">
      <color rgba="255 108 10 255"/>
    </material>
  </link>
  <gazebo reference="base_imu">
    <material>Gazebo/Orange</material>
  </gazebo>
  <gazebo reference="base_imu_joint">
    <disableFixedJointLumping>true</disableFixedJointLumping>
  </gazebo>
  <joint name="laser_link_joint" type="fixed">
    <origin rpy="0. 0. 0." xyz="0.3 0. 0.2"/>
    <parent link="base"/>
    <child link="laser_link"/>
  </joint>
  <link name="laser_link">
    <inertial>
      <origin rpy="0 0 0" xyz="0 0 0"/>
      <mass value="0.1"/>
      <inertia ixx="0.01" ixy="0" ixz="0" iyy="0.01" iyz="0" izz="0.01"/>
    </inertial>
    <visual>
      <origin rpy="0 0 0" xyz="0 0 0"/>
      <geometry>
        <cylinder length="0.05" radius="0.05"/>
      </geometry>
      <material name="">
        <color rgba="1 1 1 1"/>
      </material>
    </visual>
    <collision>
      <origin rpy="0 0 0" xyz="0 0 0"/>
      <geometry>
        <cylinder length="0.05" radius="0.05"/>
      </geometry>
    </collision>
  </link>
  <gazebo reference="laser_link">
    <material>Gazebo/Orange</material>
  </gazebo>
  <gazebo reference="laser_link_joint">
    <disableFixedJointLumping>true</disableFixedJointLumping>
  </gazebo>
  <!-- laser plugin for 'laser_link' -->
  <gazebo reference="laser_link">
    <sensor name="rplidar" type="ray">
      <pose>0 0 0 0 0 0</pose>
      <visualize>true</visualize>
      <update_rate>300</update_rate>
      <ray>
        <scan>
          <horizontal>
            <samples>720</samples>
            <resolution>1</resolution>
            <min_angle>-3</min_angle>
            <max_angle>3</max_angle>
          </horizontal>
        </scan>
        <range>
          <min>0.10</min>
          <max>100.0</max>
          <resolution>0.001</resolution>
        </range>
        <noise>
          <type>gaussian</type>
          <mean>0.0</mean>
          <stddev>0.01</stddev>
        </noise>
      </ray>
      <plugin filename="libgazebo_ros_laser.so" name="gazebo_rplidar">
        <topicName>/scan</topicName>
        <frameName>laser_link</frameName>
      </plugin>
    </sensor>
  </gazebo>
  <joint name="LF_HAA" type="revolute">
    <origin rpy="0.2 0 0" xyz="0.3285 0.072 0"/>
    <parent link="base"/>
    <child link="LF_hip"/>
    <axis xyz="1 0 0"/>
    <dynamics damping="0.2" friction="0"/>
    <limit effort="200" lower="-0.87" upper="0.87" velocity="23"/>
  </joint>
  <link name="LF_hip">
    <visual>
      <origin rpy="0 0 0" xyz="0 0 0"/>
      <geometry>
        <mesh filename="package://legged_unitree_description/meshes/b2w/hip.dae" scale="1 1 1"/>
      </geometry>
      <material name="orange"/>
    </visual>
    <collision>
      <origin rpy="1.5707963267948966 0 0" xyz="0 0 0"/>
      <geometry>
        <cylinder length="0.05" radius="0.07"/>
      </geometry>
    </collision>
    <inertial>
      <origin rpy="0 0 0" xyz="-0.009305 -0.010228 0.000264"/>
      <mass value="0.595"/>
      <inertia ixx="0.0026431" ixy="0.00019234" ixz="-6.76e-06" iyy="0.0046728" iyz="-7.16e-06" izz="0.0034208"/>
    </inertial>
  </link>
  <joint name="LF_HFE" type="revolute">
    <origin rpy="0 0 0" xyz="0 0.11973 0"/>
    <parent link="LF_hip"/>
    <child link="LF_thigh"/>
    <axis xyz="0 1 0"/>
    <dynamics damping="0.2" friction="0"/>
    <limit effort="200" lower="-94" upper="4.69" velocity="23"/>
    <pose>0 0 0 0 0 0</pose>
  </joint>
  <link name="LF_thigh">
    <visual>
      <origin rpy="0 0 0" xyz="0 0 0"/>
      <geometry>
        <mesh filename="package://legged_unitree_description/meshes/b2w/thigh.dae" scale="1 1 1"/>
      </geometry>
      <material name="orange"/>
    </visual>
    <collision>
      <origin rpy="0 1.6707963267948966 0" xyz="-0.015 0 -0.16"/>
      <geometry>
        <box size="0.32 0.0455 0.054"/>
      </geometry>
    </collision>
    <collision>
      <origin rpy="1.5707963267948966 0 0" xyz="0 -0.008 0"/>
      <geometry>
        <cylinder length="0.08" radius="0.044"/>
      </geometry>
    </collision>
    <inertial>
      <origin rpy="0 0 0" xyz="-0.004346 -0.035797 -0.044921"/>
      <mass value="0.888"/>
      <inertia ixx="0.041718" ixy="0.00055623" ixz="-0.0022768" iyy="0.041071" iyz="0.005796" izz="0.0065677"/>
    </inertial>
  </link>
  <joint name="LF_KFE" type="revolute">
    <origin rpy="0 0 0" xyz="0 0 -0.32"/>
    <parent link="LF_thigh"/>
    <child link="LF_calf"/>
    <axis xyz="0 1 0"/>
    <dynamics damping="0.2" friction="0"/>
    <limit effort="320" lower="-2.82" upper="-0.43" velocity="14"/>
    <pose>0 0 0 0 0 0</pose>
  </joint>
  <link name="LF_calf">
    <visual>
      <origin rpy="0 0 0" xyz="0 0 0"/>
      <geometry>
        <mesh filename="package://legged_unitree_description/meshes/b2w/calf.dae" scale="1 1 1"/>
      </geometry>
      <material name="orange"/>
    </visual>
    <collision>
      <origin rpy="0 1.5707963267948966 0" xyz="0.0 0 -0.175"/>
      <geometry>
        <box size="0.35 0.04 0.05"/>
      </geometry>
    </collision>
    <inertial>
      <origin rpy="0 0 0" xyz="0.006095 0.012046 -0.29122"/>
      <mass value="0.151"/>
      <inertia ixx="0.028133" ixy="0.00016307" ixz="-0.0010034" iyy="0.029251" iyz="0.0014765" izz="0.0028379"/>
    </inertial>
  </link>
  <joint dont_collapse="true" name="LF_foot" type="continuous">
    <origin rpy="0 0 0" xyz="0 0 -0.35"/>
    <parent link="LF_calf"/>
    <child link="LF_FOOT"/>
    <axis xyz="0 1 0"/>
    <limit effort="20" velocity="50"/>
    <dynamics damping="0.5" friction="0.1"/>
  </joint>
  <link name="LF_FOOT">
    <visual>
      <origin rpy="0 0 0" xyz="0 0.051053 0"/>
      <geometry>
        <mesh filename="package://legged_unitree_description/meshes/b2w/foot.dae" scale="1 1 1"/>
      </geometry>
      <material name="orange"/>
    </visual>
    <collision>
      <origin rpy="0 0 0" xyz="0 0 0"/>
      <geometry>
        <sphere radius="0.10"/>
        <!-- cylinder radius="0.1125" length="0.1"/ -->
      </geometry>
    </collision>
    <inertial>
      <origin rpy="0 0 0" xyz="0 0.051053 0"/>
      <mass value="0.118"/>
      <inertia ixx="0.004121" ixy="6E-06" ixz="-4.8E-05" iyy="0.007776" iyz="7E-06" izz="0.004108"/>
      <!-- xacro:cylinder_inertia m="${foot_mass}" r="0.1125" h="0.1"/ -->
    </inertial>
  </link>
  <gazebo reference="LF_foot">
    <disableFixedJointLumping>true</disableFixedJointLumping>
  </gazebo>
  <gazebo reference="LF_hip">
    <mu1>0.2</mu1>
    <mu2>0.2</mu2>
    <material>Gazebo/DarkGrey</material>
  </gazebo>
  <gazebo reference="LF_thigh">
    <mu1>0.2</mu1>
    <mu2>0.2</mu2>
    <self_collide>0</self_collide>
    <material>Gazebo/DarkGrey</material>
    <kp value="1000000.0"/>
    <kd value="100.0"/>
  </gazebo>
  <gazebo reference="LF_calf">
    <mu1>0.6</mu1>
    <mu2>0.6</mu2>
    <self_collide>1</self_collide>
  </gazebo>
  <gazebo reference="LF_FOOT">
    <mu1>1.0</mu1>
    <mu2>1.0</mu2>
    <self_collide>1</self_collide>
    <material>Gazebo/DarkGrey</material>
    <kp value="1000000.0"/>
    <kd value="100.0"/>
  </gazebo>
  <transmission name="LF_HAA_tran">
    <type>transmission_interface/SimpleTransmission</type>
    <joint name="LF_HAA">
      <hardwareInterface>hardware_interface/EffortJointInterface</hardwareInterface>
    </joint>
    <actuator name="LF_HAA_motor">
      <hardwareInterface>hardware_interface/EffortJointInterface</hardwareInterface>
      <mechanicalReduction>1</mechanicalReduction>
    </actuator>
  </transmission>
  <transmission name="LF_HFE_tran">
    <type>transmission_interface/SimpleTransmission</type>
    <joint name="LF_HFE">
      <hardwareInterface>hardware_interface/EffortJointInterface</hardwareInterface>
    </joint>
    <actuator name="LF_HFE_motor">
      <hardwareInterface>hardware_interface/EffortJointInterface</hardwareInterface>
      <mechanicalReduction>1</mechanicalReduction>
    </actuator>
  </transmission>
  <transmission name="LF_KFE_tran">
    <type>transmission_interface/SimpleTransmission</type>
    <joint name="LF_KFE">
      <hardwareInterface>hardware_interface/EffortJointInterface</hardwareInterface>
    </joint>
    <actuator name="LF_KFE_motor">
      <hardwareInterface>hardware_interface/EffortJointInterface</hardwareInterface>
      <mechanicalReduction>1</mechanicalReduction>
    </actuator>
  </transmission>
  <transmission name="LF_tran">
    <type>transmission_interface/SimpleTransmission</type>
    <joint name="LF_foot">
      <hardwareInterface>hardware_interface/VelocityJointInterface</hardwareInterface>
    </joint>
    <actuator name="LF_foot_motor">
      <hardwareInterface>hardware_interface/VelocityJointInterface</hardwareInterface>
      <mechanicalReduction>1</mechanicalReduction>
    </actuator>
  </transmission>
  <joint name="LH_HAA" type="revolute">
    <origin rpy="0.2 0 0" xyz="-0.3285 0.072 0"/>
    <parent link="base"/>
    <child link="LH_hip"/>
    <axis xyz="1 0 0"/>
    <dynamics damping="0.2" friction="0"/>
    <limit effort="200" lower="-0.87" upper="0.87" velocity="23"/>
  </joint>
  <link name="LH_hip">
    <visual>
      <origin rpy="0 3.141592653589793 0" xyz="0 0 0"/>
      <geometry>
        <mesh filename="package://legged_unitree_description/meshes/b2w/hip.dae" scale="1 1 1"/>
      </geometry>
      <material name="orange"/>
    </visual>
    <collision>
      <origin rpy="1.5707963267948966 0 0" xyz="0 0 0"/>
      <geometry>
        <cylinder length="0.05" radius="0.07"/>
      </geometry>
    </collision>
    <inertial>
      <origin rpy="0 0 0" xyz="0.009305 -0.010228 0.000264"/>
      <mass value="0.595"/>
      <inertia ixx="0.0026431" ixy="-0.00019234" ixz="6.76e-06" iyy="0.0046728" iyz="-7.16e-06" izz="0.0034208"/>
    </inertial>
  </link>
  <joint name="LH_HFE" type="revolute">
    <origin rpy="0 0 0" xyz="0 0.11973 0"/>
    <parent link="LH_hip"/>
    <child link="LH_thigh"/>
    <axis xyz="0 1 0"/>
    <dynamics damping="0.2" friction="0"/>
    <limit effort="200" lower="-94" upper="4.69" velocity="23"/>
    <pose>0 0 0 0 0 0</pose>
  </joint>
  <link name="LH_thigh">
    <visual>
      <origin rpy="0 0 0" xyz="0 0 0"/>
      <geometry>
        <mesh filename="package://legged_unitree_description/meshes/b2w/thigh.dae" scale="1 1 1"/>
      </geometry>
      <material name="orange"/>
    </visual>
    <collision>
      <origin rpy="0 1.6707963267948966 0" xyz="-0.015 0 -0.16"/>
      <geometry>
        <box size="0.32 0.0455 0.054"/>
      </geometry>
    </collision>
    <collision>
      <origin rpy="1.5707963267948966 0 0" xyz="0 -0.008 0"/>
      <geometry>
        <cylinder length="0.08" radius="0.044"/>
      </geometry>
    </collision>
    <inertial>
      <origin rpy="0 0 0" xyz="-0.004346 -0.035797 -0.044921"/>
      <mass value="0.888"/>
      <inertia ixx="0.041718" ixy="0.00055623" ixz="-0.0022768" iyy="0.041071" iyz="0.005796" izz="0.0065677"/>
    </inertial>
  </link>
  <joint name="LH_KFE" type="revolute">
    <origin rpy="0 0 0" xyz="0 0 -0.32"/>
    <parent link="LH_thigh"/>
    <child link="LH_calf"/>
    <axis xyz="0 1 0"/>
    <dynamics damping="0.2" friction="0"/>
    <limit effort="320" lower="-2.82" upper="-0.43" velocity="14"/>
    <pose>0 0 0 0 0 0</pose>
  </joint>
  <link name="LH_calf">
    <visual>
      <origin rpy="0 0 0" xyz="0 0 0"/>
      <geometry>
        <mesh filename="package://legged_unitree_description/meshes/b2w/calf.dae" scale="1 1 1"/>
      </geometry>
      <material name="orange"/>
    </visual>
    <collision>
      <origin rpy="0 1.5707963267948966 0" xyz="0.0 0 -0.175"/>
      <geometry>
        <box size="0.35 0.04 0.05"/>
      </geometry>
    </collision>
    <inertial>
      <origin rpy="0 0 0" xyz="0.006095 0.012046 -0.29122"/>
      <mass value="0.151"/>
      <inertia ixx="0.028133" ixy="0.00016307" ixz="-0.0010034" iyy="0.029251" iyz="0.0014765" izz="0.0028379"/>
    </inertial>
  </link>
  <joint dont_collapse="true" name="LH_foot" type="continuous">
    <origin rpy="0 0 0" xyz="0 0 -0.35"/>
    <parent link="LH_calf"/>
    <child link="LH_FOOT"/>
    <axis xyz="0 1 0"/>
    <limit effort="20" velocity="50"/>
    <dynamics damping="0.5" friction="0.1"/>
  </joint>
  <link name="LH_FOOT">
    <visual>
      <origin rpy="0 0 0" xyz="0 0.051053 0"/>
      <geometry>
        <mesh filename="package://legged_unitree_description/meshes/b2w/foot.dae" scale="1 1 1"/>
      </geometry>
      <material name="orange"/>
    </visual>
    <collision>
      <origin rpy="0 0 0" xyz="0 0 0"/>
      <geometry>
        <sphere radius="0.10"/>
        <!-- cylinder radius="0.1125" length="0.1"/ -->
      </geometry>
    </collision>
    <inertial>
      <origin rpy="0 0 0" xyz="0 0.051053 0"/>
      <mass value="0.118"/>
      <inertia ixx="0.004121" ixy="6E-06" ixz="-4.8E-05" iyy="0.007776" iyz="7E-06" izz="0.004108"/>
      <!-- xacro:cylinder_inertia m="${foot_mass}" r="0.1125" h="0.1"/ -->
    </inertial>
  </link>
  <gazebo reference="LH_foot">
    <disableFixedJointLumping>true</disableFixedJointLumping>
  </gazebo>
  <gazebo reference="LH_hip">
    <mu1>0.2</mu1>
    <mu2>0.2</mu2>
    <material>Gazebo/DarkGrey</material>
  </gazebo>
  <gazebo reference="LH_thigh">
    <mu1>0.2</mu1>
    <mu2>0.2</mu2>
    <self_collide>0</self_collide>
    <material>Gazebo/DarkGrey</material>
    <kp value="1000000.0"/>
    <kd value="100.0"/>
  </gazebo>
  <gazebo reference="LH_calf">
    <mu1>0.6</mu1>
    <mu2>0.6</mu2>
    <self_collide>1</self_collide>
  </gazebo>
  <gazebo reference="LH_FOOT">
    <mu1>1.0</mu1>
    <mu2>1.0</mu2>
    <self_collide>1</self_collide>
    <material>Gazebo/DarkGrey</material>
    <kp value="1000000.0"/>
    <kd value="100.0"/>
  </gazebo>
  <transmission name="LH_HAA_tran">
    <type>transmission_interface/SimpleTransmission</type>
    <joint name="LH_HAA">
      <hardwareInterface>hardware_interface/EffortJointInterface</hardwareInterface>
    </joint>
    <actuator name="LH_HAA_motor">
      <hardwareInterface>hardware_interface/EffortJointInterface</hardwareInterface>
      <mechanicalReduction>1</mechanicalReduction>
    </actuator>
  </transmission>
  <transmission name="LH_HFE_tran">
    <type>transmission_interface/SimpleTransmission</type>
    <joint name="LH_HFE">
      <hardwareInterface>hardware_interface/EffortJointInterface</hardwareInterface>
    </joint>
    <actuator name="LH_HFE_motor">
      <hardwareInterface>hardware_interface/EffortJointInterface</hardwareInterface>
      <mechanicalReduction>1</mechanicalReduction>
    </actuator>
  </transmission>
  <transmission name="LH_KFE_tran">
    <type>transmission_interface/SimpleTransmission</type>
    <joint name="LH_KFE">
      <hardwareInterface>hardware_interface/EffortJointInterface</hardwareInterface>
    </joint>
    <actuator name="LH_KFE_motor">
      <hardwareInterface>hardware_interface/EffortJointInterface</hardwareInterface>
      <mechanicalReduction>1</mechanicalReduction>
    </actuator>
  </transmission>
  <transmission name="LH_tran">
    <type>transmission_interface/SimpleTransmission</type>
    <joint name="LH_foot">
      <hardwareInterface>hardware_interface/VelocityJointInterface</hardwareInterface>
    </joint>
    <actuator name="LH_foot_motor">
      <hardwareInterface>hardware_interface/VelocityJointInterface</hardwareInterface>
      <mechanicalReduction>1</mechanicalReduction>
    </actuator>
  </transmission>
  <joint name="RF_HAA" type="revolute">
    <origin rpy="-0.2 0 0" xyz="0.3285 -0.072 0"/>
    <parent link="base"/>
    <child link="RF_hip"/>
    <axis xyz="1 0 0"/>
    <dynamics damping="0.2" friction="0"/>
    <limit effort="200" lower="-0.87" upper="0.87" velocity="23"/>
  </joint>
  <link name="RF_hip">
    <visual>
      <origin rpy="3.141592653589793 0 0" xyz="0 0 0"/>
      <geometry>
        <mesh filename="package://legged_unitree_description/meshes/b2w/hip.dae" scale="1 1 1"/>
      </geometry>
      <material name="orange"/>
    </visual>
    <collision>
      <origin rpy="1.5707963267948966 0 0" xyz="0 0 0"/>
      <geometry>
        <cylinder length="0.05" radius="0.07"/>
      </geometry>
    </collision>
    <inertial>
      <origin rpy="0 0 0" xyz="-0.009305 0.010228 0.000264"/>
      <mass value="0.595"/>
      <inertia ixx="0.0026431" ixy="-0.00019234" ixz="-6.76e-06" iyy="0.0046728" iyz="7.16e-06" izz="0.0034208"/>
    </inertial>
  </link>
  <joint name="RF_HFE" type="revolute">
    <origin rpy="0 0 0" xyz="0 -0.11973 0"/>
    <parent link="RF_hip"/>
    <child link="RF_thigh"/>
    <axis xyz="0 1 0"/>
    <dynamics damping="0.2" friction="0"/>
    <limit effort="200" lower="-94" upper="4.69" velocity="23"/>
    <pose>0 0 0 0 0 0</pose>
  </joint>
  <link name="RF_thigh">
    <visual>
      <origin rpy="0 0 0" xyz="0 0 0"/>
      <geometry>
        <mesh filename="package://legged_unitree_description/meshes/b2w/thigh_mirror.dae" scale="1 1 1"/>
      </geometry>
      <material name="orange"/>
    </visual>
    <collision>
      <origin rpy="0 1.6707963267948966 0" xyz="-0.015 0 -0.16"/>
      <geometry>
        <box size="0.32 0.0455 0.054"/>
      </geometry>
    </collision>
    <collision>
      <origin rpy="1.5707963267948966 0 0" xyz="0 0.008 0"/>
      <geometry>
        <cylinder length="0.08" radius="0.044"/>
      </geometry>
    </collision>
    <inertial>
      <origin rpy="0 0 0" xyz="-0.004346 0.035797 -0.044921"/>
      <mass value="0.888"/>
      <inertia ixx="0.041718" ixy="-0.00055623" ixz="-0.0022768" iyy="0.041071" iyz="-0.005796" izz="0.0065677"/>
    </inertial>
  </link>
  <joint name="RF_KFE" type="revolute">
    <origin rpy="0 0 0" xyz="0 0 -0.32"/>
    <parent link="RF_thigh"/>
    <child link="RF_calf"/>
    <axis xyz="0 1 0"/>
    <dynamics damping="0.2" friction="0"/>
    <limit effort="320" lower="-2.82" upper="-0.43" velocity="14"/>
    <pose>0 0 0 0 0 0</pose>
  </joint>
  <link name="RF_calf">
    <visual>
      <origin rpy="0 0 0" xyz="0 0 0"/>
      <geometry>
        <mesh filename="package://legged_unitree_description/meshes/b2w/calf_mirror.dae" scale="1 1 1"/>
      </geometry>
      <material name="orange"/>
    </visual>
    <collision>
      <origin rpy="0 1.5707963267948966 0" xyz="0.0 0 -0.175"/>
      <geometry>
        <box size="0.35 0.04 0.05"/>
      </geometry>
    </collision>
    <inertial>
      <origin rpy="0 0 0" xyz="0.006095 0.012046 -0.29122"/>
      <mass value="0.151"/>
      <inertia ixx="0.028133" ixy="0.00016307" ixz="-0.0010034" iyy="0.029251" iyz="0.0014765" izz="0.0028379"/>
    </inertial>
  </link>
  <joint dont_collapse="true" name="RF_foot" type="continuous">
    <origin rpy="0 0 0" xyz="0 0 -0.35"/>
    <parent link="RF_calf"/>
    <child link="RF_FOOT"/>
    <axis xyz="0 1 0"/>
    <limit effort="20" velocity="50"/>
    <dynamics damping="0.5" friction="0.1"/>
  </joint>
  <link name="RF_FOOT">
    <visual>
      <origin rpy="0 0 0" xyz="0 -0.051053 0"/>
      <geometry>
        <mesh filename="package://legged_unitree_description/meshes/b2w/foot_mirror.dae" scale="1 1 1"/>
      </geometry>
      <material name="orange"/>
    </visual>
    <collision>
      <origin rpy="0 0 0" xyz="0 0 0"/>
      <geometry>
        <sphere radius="0.10"/>
        <!-- cylinder radius="0.1125" length="0.1"/ -->
      </geometry>
    </collision>
    <inertial>
      <origin rpy="0 0 0" xyz="0 -0.051053 0"/>
      <mass value="0.118"/>
      <inertia ixx="0.004121" ixy="6E-06" ixz="-4.8E-05" iyy="0.007776" iyz="7E-06" izz="0.004108"/>
      <!-- xacro:cylinder_inertia m="${foot_mass}" r="0.1125" h="0.1"/ -->
    </inertial>
  </link>
  <gazebo reference="RF_foot">
    <disableFixedJointLumping>true</disableFixedJointLumping>
  </gazebo>
  <gazebo reference="RF_hip">
    <mu1>0.2</mu1>
    <mu2>0.2</mu2>
    <material>Gazebo/DarkGrey</material>
  </gazebo>
  <gazebo reference="RF_thigh">
    <mu1>0.2</mu1>
    <mu2>0.2</mu2>
    <self_collide>0</self_collide>
    <material>Gazebo/DarkGrey</material>
    <kp value="1000000.0"/>
    <kd value="100.0"/>
  </gazebo>
  <gazebo reference="RF_calf">
    <mu1>0.6</mu1>
    <mu2>0.6</mu2>
    <self_collide>1</self_collide>
  </gazebo>
  <gazebo reference="RF_FOOT">
    <mu1>1.0</mu1>
    <mu2>1.0</mu2>
    <self_collide>1</self_collide>
    <material>Gazebo/DarkGrey</material>
    <kp value="1000000.0"/>
    <kd value="100.0"/>
  </gazebo>
  <transmission name="RF_HAA_tran">
    <type>transmission_interface/SimpleTransmission</type>
    <joint name="RF_HAA">
      <hardwareInterface>hardware_interface/EffortJointInterface</hardwareInterface>
    </joint>
    <actuator name="RF_HAA_motor">
      <hardwareInterface>hardware_interface/EffortJointInterface</hardwareInterface>
      <mechanicalReduction>1</mechanicalReduction>
    </actuator>
  </transmission>
  <transmission name="RF_HFE_tran">
    <type>transmission_interface/SimpleTransmission</type>
    <joint name="RF_HFE">
      <hardwareInterface>hardware_interface/EffortJointInterface</hardwareInterface>
    </joint>
    <actuator name="RF_HFE_motor">
      <hardwareInterface>hardware_interface/EffortJointInterface</hardwareInterface>
      <mechanicalReduction>1</mechanicalReduction>
    </actuator>
  </transmission>
  <transmission name="RF_KFE_tran">
    <type>transmission_interface/SimpleTransmission</type>
    <joint name="RF_KFE">
      <hardwareInterface>hardware_interface/EffortJointInterface</hardwareInterface>
    </joint>
    <actuator name="RF_KFE_motor">
      <hardwareInterface>hardware_interface/EffortJointInterface</hardwareInterface>
      <mechanicalReduction>1</mechanicalReduction>
    </actuator>
  </transmission>
  <transmission name="RF_tran">
    <type>transmission_interface/SimpleTransmission</type>
    <joint name="RF_foot">
      <hardwareInterface>hardware_interface/VelocityJointInterface</hardwareInterface>
    </joint>
    <actuator name="RF_foot_motor">
      <hardwareInterface>hardware_interface/VelocityJointInterface</hardwareInterface>
      <mechanicalReduction>1</mechanicalReduction>
    </actuator>
  </transmission>
  <joint name="RH_HAA" type="revolute">
    <origin rpy="-0.2 0 0" xyz="-0.3285 -0.072 0"/>
    <parent link="base"/>
    <child link="RH_hip"/>
    <axis xyz="1 0 0"/>
    <dynamics damping="0.2" friction="0"/>
    <limit effort="200" lower="-0.87" upper="0.87" velocity="23"/>
  </joint>
  <link name="RH_hip">
    <visual>
      <origin rpy="3.141592653589793 3.141592653589793 0" xyz="0 0 0"/>
      <geometry>
        <mesh filename="package://legged_unitree_description/meshes/b2w/hip.dae" scale="1 1 1"/>
      </geometry>
      <material name="orange"/>
    </visual>
    <collision>
      <origin rpy="1.5707963267948966 0 0" xyz="0 0 0"/>
      <geometry>
        <cylinder length="0.05" radius="0.07"/>
      </geometry>
    </collision>
    <inertial>
      <origin rpy="0 0 0" xyz="0.009305 0.010228 0.000264"/>
      <mass value="0.595"/>
      <inertia ixx="0.0026431" ixy="0.00019234" ixz="6.76e-06" iyy="0.0046728" iyz="7.16e-06" izz="0.0034208"/>
    </inertial>
  </link>
  <joint name="RH_HFE" type="revolute">
    <origin rpy="0 0 0" xyz="0 -0.11973 0"/>
    <parent link="RH_hip"/>
    <child link="RH_thigh"/>
    <axis xyz="0 1 0"/>
    <dynamics damping="0.2" friction="0"/>
    <limit effort="200" lower="-94" upper="4.69" velocity="23"/>
    <pose>0 0 0 0 0 0</pose>
  </joint>
  <link name="RH_thigh">
    <visual>
      <origin rpy="0 0 0" xyz="0 0 0"/>
      <geometry>
        <mesh filename="package://legged_unitree_description/meshes/b2w/thigh_mirror.dae" scale="1 1 1"/>
      </geometry>
      <material name="orange"/>
    </visual>
    <collision>
      <origin rpy="0 1.6707963267948966 0" xyz="-0.015 0 -0.16"/>
      <geometry>
        <box size="0.32 0.0455 0.054"/>
      </geometry>
    </collision>
    <collision>
      <origin rpy="1.5707963267948966 0 0" xyz="0 0.008 0"/>
      <geometry>
        <cylinder length="0.08" radius="0.044"/>
      </geometry>
    </collision>
    <inertial>
      <origin rpy="0 0 0" xyz="-0.004346 0.035797 -0.044921"/>
      <mass value="0.888"/>
      <inertia ixx="0.041718" ixy="-0.00055623" ixz="-0.0022768" iyy="0.041071" iyz="-0.005796" izz="0.0065677"/>
    </inertial>
  </link>
  <joint name="RH_KFE" type="revolute">
    <origin rpy="0 0 0" xyz="0 0 -0.32"/>
    <parent link="RH_thigh"/>
    <child link="RH_calf"/>
    <axis xyz="0 1 0"/>
    <dynamics damping="0.2" friction="0"/>
    <limit effort="320" lower="-2.82" upper="-0.43" velocity="14"/>
    <pose>0 0 0 0 0 0</pose>
  </joint>
  <link name="RH_calf">
    <visual>
      <origin rpy="0 0 0" xyz="0 0 0"/>
      <geometry>
        <mesh filename="package://legged_unitree_description/meshes/b2w/calf_mirror.dae" scale="1 1 1"/>
      </geometry>
      <material name="orange"/>
    </visual>
    <collision>
      <origin rpy="0 1.5707963267948966 0" xyz="0.0 0 -0.175"/>
      <geometry>
        <box size="0.35 0.04 0.05"/>
      </geometry>
    </collision>
    <inertial>
      <origin rpy="0 0 0" xyz="0.006095 0.012046 -0.29122"/>
      <mass value="0.151"/>
      <inertia ixx="0.028133" ixy="0.00016307" ixz="-0.0010034" iyy="0.029251" iyz="0.0014765" izz="0.0028379"/>
    </inertial>
  </link>
  <joint dont_collapse="true" name="RH_foot" type="continuous">
    <origin rpy="0 0 0" xyz="0 0 -0.35"/>
    <parent link="RH_calf"/>
    <child link="RH_FOOT"/>
    <axis xyz="0 1 0"/>
    <limit effort="20" velocity="50"/>
    <dynamics damping="0.5" friction="0.1"/>
  </joint>
  <link name="RH_FOOT">
    <visual>
      <origin rpy="0 0 0" xyz="0 -0.051053 0"/>
      <geometry>
        <mesh filename="package://legged_unitree_description/meshes/b2w/foot_mirror.dae" scale="1 1 1"/>
      </geometry>
      <material name="orange"/>
    </visual>
    <collision>
      <origin rpy="0 0 0" xyz="0 0 0"/>
      <geometry>
        <sphere radius="0.10"/>
        <!-- cylinder radius="0.1125" length="0.1"/ -->
      </geometry>
    </collision>
    <inertial>
      <origin rpy="0 0 0" xyz="0 -0.051053 0"/>
      <mass value="0.118"/>
      <inertia ixx="0.004121" ixy="6E-06" ixz="-4.8E-05" iyy="0.007776" iyz="7E-06" izz="0.004108"/>
      <!-- xacro:cylinder_inertia m="${foot_mass}" r="0.1125" h="0.1"/ -->
    </inertial>
  </link>
  <gazebo reference="RH_foot">
    <disableFixedJointLumping>true</disableFixedJointLumping>
  </gazebo>
  <gazebo reference="RH_hip">
    <mu1>0.2</mu1>
    <mu2>0.2</mu2>
    <material>Gazebo/DarkGrey</material>
  </gazebo>
  <gazebo reference="RH_thigh">
    <mu1>0.2</mu1>
    <mu2>0.2</mu2>
    <self_collide>0</self_collide>
    <material>Gazebo/DarkGrey</material>
    <kp value="1000000.0"/>
    <kd value="100.0"/>
  </gazebo>
  <gazebo reference="RH_calf">
    <mu1>0.6</mu1>
    <mu2>0.6</mu2>
    <self_collide>1</self_collide>
  </gazebo>
  <gazebo reference="RH_FOOT">
    <mu1>1.0</mu1>
    <mu2>1.0</mu2>
    <self_collide>1</self_collide>
    <material>Gazebo/DarkGrey</material>
    <kp value="1000000.0"/>
    <kd value="100.0"/>
  </gazebo>
  <transmission name="RH_HAA_tran">
    <type>transmission_interface/SimpleTransmission</type>
    <joint name="RH_HAA">
      <hardwareInterface>hardware_interface/EffortJointInterface</hardwareInterface>
    </joint>
    <actuator name="RH_HAA_motor">
      <hardwareInterface>hardware_interface/EffortJointInterface</hardwareInterface>
      <mechanicalReduction>1</mechanicalReduction>
    </actuator>
  </transmission>
  <transmission name="RH_HFE_tran">
    <type>transmission_interface/SimpleTransmission</type>
    <joint name="RH_HFE">
      <hardwareInterface>hardware_interface/EffortJointInterface</hardwareInterface>
    </joint>
    <actuator name="RH_HFE_motor">
      <hardwareInterface>hardware_interface/EffortJointInterface</hardwareInterface>
      <mechanicalReduction>1</mechanicalReduction>
    </actuator>
  </transmission>
  <transmission name="RH_KFE_tran">
    <type>transmission_interface/SimpleTransmission</type>
    <joint name="RH_KFE">
      <hardwareInterface>hardware_interface/EffortJointInterface</hardwareInterface>
    </joint>
    <actuator name="RH_KFE_motor">
      <hardwareInterface>hardware_interface/EffortJointInterface</hardwareInterface>
      <mechanicalReduction>1</mechanicalReduction>
    </actuator>
  </transmission>
  <transmission name="RH_tran">
    <type>transmission_interface/SimpleTransmission</type>
    <joint name="RH_foot">
      <hardwareInterface>hardware_interface/VelocityJointInterface</hardwareInterface>
    </joint>
    <actuator name="RH_foot_motor">
      <hardwareInterface>hardware_interface/VelocityJointInterface</hardwareInterface>
      <mechanicalReduction>1</mechanicalReduction>
    </actuator>
  </transmission>
  <joint name="arm_rot_1" type="revolute">
    <origin rpy="1.5708 -1.2246E-16 -1.57" xyz="0 0 0.07"/>
    <parent link="base"/>
    <child link="arm_link_1"/>
    <axis xyz="0 1 0"/>
    <limit effort="500" lower="-3.1415926" upper="3.1415926" velocity="12.56"/>
    <dynamics damping="0.1" friction="0.1"/>
  </joint>
  <link name="arm_link_1">
    <inertial>
      <origin rpy="0 0 0" xyz="4.5445E-08 0.055988 -3.3733E-07"/>
      <mass value="0.25"/>
      <inertia ixx="0.001" ixy="0" ixz="0" iyy="0.001" iyz="0" izz="0.001"/>
    </inertial>
    <visual>
      <origin rpy="0 0 0" xyz="0 0 0"/>
      <geometry>
        <mesh filename="package://legged_unitree_description/meshes/b2w/arm_link_1.STL"/>
      </geometry>
      <material name="">
        <color rgba="0.79216 0.81961 0.93333 1"/>
      </material>
    </visual>
    <collision>
      <origin rpy="0 0 0" xyz="0 0 0"/>
      <geometry>
        <mesh filename="package://legged_unitree_description/meshes/b2w/arm_link_1.STL"/>
      </geometry>
    </collision>
  </link>
  <link name="arm_link_2">
    <inertial>
      <origin rpy="0 0 0" xyz="4.1945E-10 0.2726 -9.6287E-12"/>
      <mass value="5.1205"/>
      <inertia ixx="0.1" ixy="0" ixz="0" iyy="0.001" iyz="0" izz="0.01"/>
    </inertial>
    <visual>
      <origin rpy="0 0 0" xyz="0 0 0"/>
      <geometry>
        <mesh filename="package://legged_unitree_description/meshes/b2w/arm_link_2.STL"/>
      </geometry>
      <material name="">
        <color rgba="0.79216 0.81961 0.93333 1"/>
      </material>
    </visual>
    <collision>
      <origin rpy="0 0 0" xyz="0 0 0"/>
      <geometry>
        <mesh filename="package://legged_unitree_description/meshes/b2w/arm_link_2.STL"/>
      </geometry>
    </collision>
  </link>
  <joint name="arm_rot_2" type="revolute">
    <origin rpy="3.1416 0 3.1416" xyz="0 0.10001 0"/>
    <parent link="arm_link_1"/>
    <child link="arm_link_2"/>
    <axis xyz="1 0 0"/>
    <limit effort="500" lower="-1.5708" upper="1.5708" velocity="12.56"/>
    <dynamics damping="0.1" friction="0.1"/>
  </joint>
  <link name="arm_link_3">
    <inertial>
      <origin rpy="0 0 0" xyz="-3.4632E-18 0.28121 1.1102E-16"/>
      <mass value="0.1"/>
      <inertia ixx="0.001" ixy="0" ixz="0" iyy="0.001" iyz="0" izz="0.001"/>
    </inertial>
    <visual>
      <origin rpy="0 0 0" xyz="0 0 0"/>
      <geometry>
        <mesh filename="package://legged_unitree_description/meshes/b2w/arm_link_3.STL"/>
      </geometry>
      <material name="">
        <color rgba="0.79216 0.81961 0.93333 1"/>
      </material>
    </visual>
    <collision>
      <origin rpy="0 0 0" xyz="0 0 0"/>
      <geometry>
        <mesh filename="package://legged_unitree_description/meshes/b2w/arm_link_3.STL"/>
      </geometry>
    </collision>
  </link>
  <joint name="arm_rot_3" type="revolute">
    <origin rpy="1.5708 0 0" xyz="0 0.6 0"/>
    <parent link="arm_link_2"/>
    <child link="arm_link_3"/>
    <axis xyz="1 0 0"/>
    <limit effort="500" lower="-3.1415" upper="1.5708" velocity="12.56"/>
    <dynamics damping="0.1" friction="0.1"/>
  </joint>
  <link name="arm_link_4">
    <inertial>
      <origin rpy="0 0 0" xyz="1.9004E-18 0.049824 0"/>
      <mass value="0.1"/>
      <inertia ixx="0.00011174" ixy="0" ixz="0" iyy="0.00011174" iyz="0" izz="0.00011749"/>
    </inertial>
    <visual>
      <origin rpy="0 0 0" xyz="0 0 0"/>
      <geometry>
        <mesh filename="package://legged_unitree_description/meshes/b2w/arm_link_4.STL"/>
      </geometry>
      <material name="">
        <color rgba="0.79216 0.81961 0.93333 1"/>
      </material>
    </visual>
    <collision>
      <origin rpy="0 0 0" xyz="0 0 0"/>
      <geometry>
        <mesh filename="package://legged_unitree_description/meshes/b2w/arm_link_4.STL"/>
      </geometry>
    </collision>
  </link>
  <joint name="arm_rot_4" type="revolute">
    <origin rpy="0 0 0" xyz="0 0.56 0"/>
    <parent link="arm_link_3"/>
    <child link="arm_link_4"/>
    <axis xyz="0 1 0"/>
    <limit effort="1" lower="-3.1415" upper="3.1415" velocity="12.56"/>
    <dynamics damping="0.1" friction="0.1"/>
  </joint>
  <link name="arm_link_5">
    <inertial>
      <origin rpy="0 0 0" xyz="-1.1102E-16 -0.014377 -2.4389E-17"/>
      <mass value="0.01"/>
      <inertia ixx="3.295E-05" ixy="0" ixz="0" iyy="2.0685E-05" iyz="0" izz="3.7289E-05"/>
    </inertial>
    <visual>
      <origin rpy="0 0 0" xyz="0 0 0"/>
      <geometry>
        <mesh filename="package://legged_unitree_description/meshes/b2w/arm_link_5.STL"/>
      </geometry>
      <material name="">
        <color rgba="0.79216 0.81961 0.93333 1"/>
      </material>
    </visual>
    <collision>
      <origin rpy="0 0 0" xyz="0 0 0"/>
      <geometry>
        <mesh filename="package://legged_unitree_description/meshes/b2w/arm_link_5.STL"/>
      </geometry>
    </collision>
  </link>
  <joint name="arm_rot_5" type="revolute">
    <origin rpy="-1.5708 0 1.5708" xyz="0 0.08 0"/>
    <parent link="arm_link_4"/>
    <child link="arm_link_5"/>
    <axis xyz="0 0 -1"/>
    <limit effort="1" lower="-3.1415" upper="0" velocity="12.56"/>
    <dynamics damping="0.1" friction="0.1"/>
  </joint>
  <link name="arm_link_6">
    <inertial>
      <origin rpy="0 0 0" xyz="-2.2204E-16 -0.017582 -6.0852E-17"/>
      <mass value="0.01"/>
      <inertia ixx="4.4304E-05" ixy="0" ixz="0" iyy="4.6087E-05" iyz="0" izz="6.4353E-06"/>
    </inertial>
    <visual>
      <origin rpy="0 0 0" xyz="0 0 0"/>
      <geometry>
        <mesh filename="package://legged_unitree_description/meshes/b2w/arm_link_6.STL"/>
      </geometry>
      <material name="">
        <color rgba="0.79216 0.81961 0.93333 1"/>
      </material>
    </visual>
    <collision>
      <origin rpy="0 0 0" xyz="0 0 0"/>
      <geometry>
        <mesh filename="package://legged_unitree_description/meshes/b2w/arm_link_6.STL"/>
      </geometry>
    </collision>
  </link>
  <joint name="arm_rot_6" type="revolute">
    <origin rpy="0 0 0" xyz="0 -0.025 0"/>
    <parent link="arm_link_5"/>
    <child link="arm_link_6"/>
    <axis xyz="0 1 0"/>
    <limit effort="1" lower="-3.1415" upper="3.1415" velocity="12.56"/>
    <dynamics damping="0.1" friction="0.1"/>
  </joint>
  <link name="finger_link_1">
    <inertial>
      <origin rpy="0 0 0" xyz="0.0022619 0.033929 -1.1102E-16"/>
      <mass value="0.01"/>
      <inertia ixx="8.7174E-06" ixy="0" ixz="0" iyy="1.347E-06" iyz="0" izz="7.4361E-06"/>
    </inertial>
    <!--inertia
            ixx="0.001"
            ixy="0"
            ixz="0"
            iyy="0.001"
            iyz="0"
            izz="0.001" />
        </inertial-->
    <visual>
      <origin rpy="0 0 0" xyz="0 0 0"/>
      <geometry>
        <mesh filename="package://legged_unitree_description/meshes/b2w/finger_link_1.STL"/>
      </geometry>
      <material name="">
        <color rgba="0.79216 0.81961 0.93333 1"/>
      </material>
    </visual>
    <collision>
      <origin rpy="0 0 0" xyz="0 0 0"/>
      <geometry>
        <mesh filename="package://legged_unitree_description/meshes/b2w/finger_link_1.STL"/>
      </geometry>
    </collision>
  </link>
  <joint name="finger_pri_1" type="prismatic">
    <origin rpy="3.1416 1.5708 0" xyz="0 -0.025 -0.045"/>
    <parent link="arm_link_6"/>
    <child link="finger_link_1"/>
    <axis xyz="-1 0 0"/>
    <limit effort="1" lower="0" upper="0.04" velocity="12.56"/>
    <dynamics damping="0.1" friction="0.1"/>
  </joint>
  <link name="finger_link_2">
    <inertial>
      <origin rpy="0 0 0" xyz="0.0022619 0.033929 0"/>
      <mass value="0.01"/>
      <inertia ixx="8.7174E-06" ixy="1.1268E-07" ixz="0" iyy="1.347E-06" iyz="0" izz="7.4361E-06"/>
    </inertial>
    <!--inertia
            ixx="0.001"
            ixy="0"
            ixz="0"
            iyy="0.001"
            iyz="0"
            izz="0.001" />
        </inertial-->
    <visual>
      <origin rpy="0 0 0" xyz="0 0 0"/>
      <geometry>
        <mesh filename="package://legged_unitree_description/meshes/b2w/finger_link_2.STL"/>
      </geometry>
      <material name="">
        <color rgba="0.79216 0.81961 0.93333 1"/>
      </material>
    </visual>
    <collision>
      <origin rpy="0 0 0" xyz="0 0 0"/>
      <geometry>
        <mesh filename="package://legged_unitree_description/meshes/b2w/finger_link_2.STL"/>
      </geometry>
    </collision>
  </link>
  <joint name="finger_pri_2" type="prismatic">
    <origin rpy="3.1416 -1.5708 0" xyz="0 -0.025 0.045"/>
    <parent link="arm_link_6"/>
    <child link="finger_link_2"/>
    <axis xyz="-1 0 0"/>
    <limit effort="1" lower="0" upper="0.04" velocity="12.56"/>
    <mimic joint="finger_pri_1"/>
    <dynamics damping="0.1" friction="0.1"/>
  </joint>
  <transmission name="trans2">
    <type>transmission_interface/SimpleTransmission</type>
    <joint name="arm_rot_1">
      <hardwareInterface>hardware_interface/EffortJointInterface</hardwareInterface>
    </joint>
    <actuator name="motor2">
      <hardwareInterface>hardware_interface/EffortJointInterface</hardwareInterface>
      <mechanicalReduction>1</mechanicalReduction>
    </actuator>
  </transmission>
  <transmission name="trans2">
    <type>transmission_interface/SimpleTransmission</type>
    <joint name="arm_rot_2">
      <hardwareInterface>hardware_interface/EffortJointInterface</hardwareInterface>
    </joint>
    <actuator name="motor2">
      <hardwareInterface>hardware_interface/EffortJointInterface</hardwareInterface>
      <mechanicalReduction>1</mechanicalReduction>
    </actuator>
  </transmission>
  <transmission name="trans2">
    <type>transmission_interface/SimpleTransmission</type>
    <joint name="arm_rot_3">
      <hardwareInterface>hardware_interface/EffortJointInterface</hardwareInterface>
    </joint>
    <actuator name="motor2">
      <hardwareInterface>hardware_interface/EffortJointInterface</hardwareInterface>
      <mechanicalReduction>1</mechanicalReduction>
    </actuator>
  </transmission>
  <transmission name="trans2">
    <type>transmission_interface/SimpleTransmission</type>
    <joint name="arm_rot_4">
      <hardwareInterface>hardware_interface/EffortJointInterface</hardwareInterface>
    </joint>
    <actuator name="motor2">
      <hardwareInterface>hardware_interface/EffortJointInterface</hardwareInterface>
      <mechanicalReduction>1</mechanicalReduction>
    </actuator>
  </transmission>
  <transmission name="trans2">
    <type>transmission_interface/SimpleTransmission</type>
    <joint name="arm_rot_5">
      <hardwareInterface>hardware_interface/EffortJointInterface</hardwareInterface>
    </joint>
    <actuator name="motor2">
      <hardwareInterface>hardware_interface/EffortJointInterface</hardwareInterface>
      <mechanicalReduction>1</mechanicalReduction>
    </actuator>
  </transmission>
  <transmission name="trans2">
    <type>transmission_interface/SimpleTransmission</type>
    <joint name="arm_rot_6">
      <hardwareInterface>hardware_interface/EffortJointInterface</hardwareInterface>
    </joint>
    <actuator name="motor2">
      <hardwareInterface>hardware_interface/EffortJointInterface</hardwareInterface>
      <mechanicalReduction>1</mechanicalReduction>
    </actuator>
  </transmission>
  <transmission name="trans2">
    <type>transmission_interface/SimpleTransmission</type>
    <joint name="finger_pri_1">
      <hardwareInterface>hardware_interface/EffortJointInterface</hardwareInterface>
    </joint>
    <actuator name="motor2">
      <hardwareInterface>hardware_interface/EffortJointInterface</hardwareInterface>
      <mechanicalReduction>1</mechanicalReduction>
    </actuator>
  </transmission>
  <transmission name="trans2">
    <type>transmission_interface/SimpleTransmission</type>
    <joint name="finger_pri_2">
      <hardwareInterface>hardware_interface/EffortJointInterface</hardwareInterface>
    </joint>
    <actuator name="motor2">
      <hardwareInterface>hardware_interface/EffortJointInterface</hardwareInterface>
      <mechanicalReduction>1</mechanicalReduction>
    </actuator>
  </transmission>
  <gazebo reference="arm_rot_1">
    <implicitSpringDamper>1</implicitSpringDamper>
  </gazebo>
  <gazebo reference="arm_rot_2">
    <implicitSpringDamper>1</implicitSpringDamper>
  </gazebo>
  <gazebo reference="arm_rot_3">
    <implicitSpringDamper>1</implicitSpringDamper>
  </gazebo>
  <gazebo reference="arm_rot_4">
    <implicitSpringDamper>1</implicitSpringDamper>
  </gazebo>
  <gazebo reference="arm_rot_5">
    <implicitSpringDamper>1</implicitSpringDamper>
  </gazebo>
  <gazebo reference="arm_rot_6">
    <implicitSpringDamper>1</implicitSpringDamper>
  </gazebo>
  <gazebo reference="finger_pri_1">
    <implicitSpringDamper>1</implicitSpringDamper>
  </gazebo>
  <gazebo reference="finger_pri_2">
    <implicitSpringDamper>1</implicitSpringDamper>
  </gazebo>
  <gazebo reference="arm_base_link">
    <self_collide>false</self_collide>
    <material>Gazebo/DarkGrey</material>
  </gazebo>
  <gazebo reference="arm_link_1">
    <self_collide>false</self_collide>
    <material>Gazebo/DarkGrey</material>
  </gazebo>
  <gazebo reference="arm_link_2">
    <self_collide>false</self_collide>
    <material>Gazebo/DarkGrey</material>
  </gazebo>
  <gazebo reference="arm_link_3">
    <self_collide>false</self_collide>
    <material>Gazebo/DarkGrey</material>
  </gazebo>
  <gazebo reference="arm_link_4">
    <self_collide>false</self_collide>
    <material>Gazebo/DarkGrey</material>
  </gazebo>
  <gazebo reference="arm_link_5">
    <self_collide>false</self_collide>
    <material>Gazebo/DarkGrey</material>
  </gazebo>
  <gazebo reference="arm_link_6">
    <self_collide>false</self_collide>
    <material>Gazebo/DarkGrey</material>
  </gazebo>
  <gazebo reference="finger_link_1">
    <self_collide>false</self_collide>
    <material>Gazebo/DarkGrey</material>
  </gazebo>
  <gazebo reference="finger_link_2">
    <self_collide>false</self_collide>
    <material>Gazebo/DarkGrey</material>
  </gazebo>
</robot>

