<?xml version="1.0" ?>
<!-- =================================================================================== -->
<!-- |    This document was autogenerated by xacro from robot.xacro                    | -->
<!-- |    EDITING THIS FILE BY HAND IS NOT RECOMMENDED                                 | -->
<!-- =================================================================================== -->
<robot name="robot">
  <material name="black">
    <color rgba="0.0 0.0 0.0 1.0"/>
  </material>
  <material name="blue">
    <color rgba="0.0 0.0 0.8 1.0"/>
  </material>
  <material name="green">
    <color rgba="0.0 0.8 0.0 1.0"/>
  </material>
  <material name="grey">
    <color rgba="0.2 0.2 0.2 1.0"/>
  </material>
  <material name="silver">
    <color rgba="0.9137254901960784 0.9137254901960784 0.8470588235294118 1.0"/>
  </material>
  <material name="orange">
    <color rgba="1.0 0.4235294117647059 0.0392156862745098 1.0"/>
  </material>
  <material name="brown">
    <color rgba="0.8705882352941177 0.8117647058823529 0.7647058823529411 1.0"/>
  </material>
  <material name="red">
    <color rgba="0.8 0.0 0.0 1.0"/>
  </material>
  <material name="white">
    <color rgba="1.0 1.0 1.0 1.0"/>
  </material>
  <gazebo>
    <plugin filename="libgazebo_ros_skid_steer_drive.so" name="skid_steer_drive_controller">
      <robotNamespace>/zrobo</robotNamespace>
      <leftFrontJoint>LF_foot</leftFrontJoint>
      <rightFrontJoint>RF_foot</rightFrontJoint>
      <leftRearJoint>LH_foot</leftRearJoint>
      <rightRearJoint>RH_foot</rightRearJoint>
      <wheelSeparation>0.4</wheelSeparation>
      <wheelDiameter>0.225</wheelDiameter>
      <robotBaseFrame>base</robotBaseFrame>
      <odometryFrame>odom1</odometryFrame>
      <odometryTopic>odom1</odometryTopic>
      <commandTopic>cmd_vel</commandTopic>
      <torque>60</torque>
      <updateRate>100</updateRate>
      <publishWheelTF>true</publishWheelTF>
      <publishTF>true</publishTF>
      <publishWheelJointState>false</publishWheelJointState>
      <alwaysOn>true</alwaysOn>
      <legacyMode>true</legacyMode>
      <broadcastTF>false</broadcastTF>
    </plugin>
  </gazebo>
  <gazebo>
    <plugin filename="libgazebo_ros_p3d.so" name="p3d_base_controller">
      <alwaysOn>true</alwaysOn>
      <updateRate>1000.0</updateRate>
      <bodyName>base</bodyName>
      <topicName>ground_truth/state</topicName>
      <gaussianNoise>0</gaussianNoise>
      <frameName>world</frameName>
      <xyzOffsets>0 0 0</xyzOffsets>
      <rpyOffsets>0 0 0</rpyOffsets>
    </plugin>
  </gazebo>
  <gazebo reference="base_link">
    <maxVel>100.</maxVel>
    <kp>10000.</kp>
    <kd>0.</kd>
  </gazebo>
  <gazebo reference="stick_link">
    <mu1>0.2</mu1>
    <mu2>0.2</mu2>
    <material>Gazebo/White</material>
  </gazebo>
  <!-- Z1 arm -->
  <gazebo reference="z1_link_0">
    <material>Gazebo/Grey</material>
  </gazebo>
  <gazebo reference="z1_link_1">
    <self_collide>true</self_collide>
    <material>Gazebo/Grey</material>
    <provideFeedback>true</provideFeedback>
  </gazebo>
  <gazebo reference="z1_link_2">
    <self_collide>true</self_collide>
    <material>Gazebo/Grey</material>
    <provideFeedback>true</provideFeedback>
  </gazebo>
  <gazebo reference="z1_link_3">
    <self_collide>true</self_collide>
    <material>Gazebo/Grey</material>
    <provideFeedback>true</provideFeedback>
  </gazebo>
  <gazebo reference="z1_link_4">
    <self_collide>true</self_collide>
    <material>Gazebo/Grey</material>
    <provideFeedback>true</provideFeedback>
  </gazebo>
  <gazebo reference="z1_link_5">
    <self_collide>true</self_collide>
    <material>Gazebo/Grey</material>
    <provideFeedback>true</provideFeedback>
  </gazebo>
  <gazebo reference="z1_link_6">
    <self_collide>true</self_collide>
    <material>Gazebo/Grey</material>
    <provideFeedback>true</provideFeedback>
  </gazebo>
  <gazebo reference="gripperStator">
    <self_collide>true</self_collide>
    <material>Gazebo/Black</material>
  </gazebo>
  <gazebo reference="gripperMover">
    <self_collide>true</self_collide>
    <material>Gazebo/Black</material>
  </gazebo>
  <gazebo reference="camera_support_1">
    <self_collide>false</self_collide>
    <material>Gazebo/Black</material>
  </gazebo>
  <gazebo reference="camera_support_2">
    <self_collide>false</self_collide>
    <material>Gazebo/Black</material>
  </gazebo>
  <gazebo reference="camera_support_3">
    <self_collide>false</self_collide>
    <material>Gazebo/Black</material>
  </gazebo>
  <gazebo reference="camera">
    <self_collide>false</self_collide>
    <material>Gazebo/Black</material>
  </gazebo>
  <gazebo reference="camera_cover">
    <self_collide>false</self_collide>
    <material>Gazebo/DarkGrey</material>
  </gazebo>
  <!-- <xacro:property name="stick_mass" value="0.00001"/> -->
  <!-- <xacro:property name="stick_radius" value="0.01"/>
    <xacro:property name="stick_length" value="0.2"/> -->
  <!-- <xacro:property name="stick_mass" value="0.00001"/> -->
  <!-- <xacro:property name="stick_radius" value="0.01"/>
    <xacro:property name="stick_length" value="0.2"/> -->
  <!-- Debug mode will hung up the robot, use "true" or "false" to switch it. -->
  <!-- <xacro:if value="true">
        <link name="world"/>
        <joint name="base_static_joint" type="fixed">
            <origin rpy="0 0 0" xyz="0 0 0"/>
            <parent link="world"/>
            <child link="base"/>
        </joint>
    </xacro:if> -->
  <!-- b2w robot -->
  <link name="base">
    <visual>
      <origin rpy="0 0 0" xyz="0 0 0"/>
      <geometry>
        <mesh filename="package://qm_description/meshes/quadruped/b2w/trunk.dae" scale="1 1 1"/>
      </geometry>
    </visual>
    <collision>
      <origin rpy="0 0 0" xyz="0 0 0"/>
      <geometry>
        <box size="0.5 0.28 0.15"/>
      </geometry>
    </collision>
    <inertial>
      <origin rpy="0 0 0" xyz="-0.000458 0.005261 0.000665"/>
      <mass value="16.0"/>
      <inertia ixx="0.0158533" ixy="-3.66e-05" ixz="-6.11e-05" iyy="0.0377999" iyz="-2.75e-05" izz="0.0456542"/>
    </inertial>
  </link>
  <!-- Imu is fixed to the base link -->
  <joint name="base_imu_joint" type="fixed">
    <origin rpy="0. 0. 0." xyz="0. 0. 0."/>
    <parent link="base"/>
    <child link="base_imu"/>
  </joint>
  <!-- Imu link -->
  <link name="base_imu">
    <inertial>
      <mass value="0.01"/>
      <origin rpy="0 0 0" xyz="0 0 0"/>
      <inertia ixx="0.000001" ixy="0" ixz="0" iyy="0.000001" iyz="0" izz="0.000001"/>
    </inertial>
    <visual>
      <origin rpy="0 0 0" xyz="0 0 0"/>
      <geometry>
        <box size="0.015 0.015 0.004"/>
      </geometry>
    </visual>
    <material name="orange">
      <color rgba="255 108 10 255"/>
    </material>
  </link>
  <gazebo reference="base_imu">
    <material>Gazebo/Orange</material>
  </gazebo>
  <gazebo reference="base_imu_joint">
    <disableFixedJointLumping>true</disableFixedJointLumping>
  </gazebo>
  <joint name="LF_HAA" type="revolute">
    <origin rpy="0.2 0 0" xyz="0.3285 0.072 0"/>
    <parent link="base"/>
    <child link="LF_hip"/>
    <axis xyz="1 0 0"/>
    <dynamics damping="0.2" friction="0"/>
    <limit effort="200" lower="-0.87" upper="0.87" velocity="23"/>
  </joint>
  <link name="LF_hip">
    <visual>
      <origin rpy="0 0 0" xyz="0 0 0"/>
      <geometry>
        <mesh filename="package://qm_description/meshes/quadruped/b2w/hip.dae" scale="1 1 1"/>
      </geometry>
      <material name="orange"/>
    </visual>
    <collision>
      <origin rpy="1.5707963267948966 0 0" xyz="0 0 0"/>
      <geometry>
        <cylinder length="0.05" radius="0.07"/>
      </geometry>
    </collision>
    <inertial>
      <origin rpy="0 0 0" xyz="-0.009305 -0.010228 0.000264"/>
      <mass value="0.595"/>
      <inertia ixx="0.0026431" ixy="0.00019234" ixz="-6.76e-06" iyy="0.0046728" iyz="-7.16e-06" izz="0.0034208"/>
    </inertial>
  </link>
  <joint name="LF_HFE" type="revolute">
    <origin rpy="0 0 0" xyz="0 0.11973 0"/>
    <parent link="LF_hip"/>
    <child link="LF_thigh"/>
    <axis xyz="0 1 0"/>
    <dynamics damping="0.2" friction="0"/>
    <limit effort="200" lower="-94" upper="4.69" velocity="23"/>
    <pose>0 0 0 0 0 0</pose>
  </joint>
  <link name="LF_thigh">
    <visual>
      <origin rpy="0 0 0" xyz="0 0 0"/>
      <geometry>
        <mesh filename="package://qm_description/meshes/quadruped/b2w/thigh.dae" scale="1 1 1"/>
      </geometry>
      <material name="orange"/>
    </visual>
    <collision>
      <origin rpy="0 1.6707963267948966 0" xyz="-0.015 0 -0.16"/>
      <geometry>
        <box size="0.32 0.0455 0.054"/>
      </geometry>
    </collision>
    <collision>
      <origin rpy="1.5707963267948966 0 0" xyz="0 -0.008 0"/>
      <geometry>
        <cylinder length="0.08" radius="0.044"/>
      </geometry>
    </collision>
    <inertial>
      <origin rpy="0 0 0" xyz="-0.004346 -0.035797 -0.044921"/>
      <mass value="0.888"/>
      <inertia ixx="0.041718" ixy="0.00055623" ixz="-0.0022768" iyy="0.041071" iyz="0.005796" izz="0.0065677"/>
    </inertial>
  </link>
  <joint name="LF_KFE" type="revolute">
    <origin rpy="0 0 0" xyz="0 0 -0.32"/>
    <parent link="LF_thigh"/>
    <child link="LF_calf"/>
    <axis xyz="0 1 0"/>
    <dynamics damping="0.2" friction="0"/>
    <limit effort="320" lower="-2.82" upper="-0.43" velocity="14"/>
    <pose>0 0 0 0 0 0</pose>
  </joint>
  <link name="LF_calf">
    <visual>
      <origin rpy="0 0 0" xyz="0 0 0"/>
      <geometry>
        <mesh filename="package://qm_description/meshes/quadruped/b2w/calf.dae" scale="1 1 1"/>
      </geometry>
      <material name="orange"/>
    </visual>
    <collision>
      <origin rpy="0 1.5707963267948966 0" xyz="0.0 0 -0.175"/>
      <geometry>
        <box size="0.35 0.04 0.05"/>
      </geometry>
    </collision>
    <inertial>
      <origin rpy="0 0 0" xyz="0.006095 0.012046 -0.29122"/>
      <mass value="0.151"/>
      <inertia ixx="0.028133" ixy="0.00016307" ixz="-0.0010034" iyy="0.029251" iyz="0.0014765" izz="0.0028379"/>
    </inertial>
  </link>
  <joint dont_collapse="true" name="LF_foot" type="continuous">
    <origin rpy="0 0 0" xyz="0 0 -0.35"/>
    <parent link="LF_calf"/>
    <child link="LF_FOOT"/>
    <axis xyz="0 1 0"/>
    <limit effort="20" velocity="50"/>
    <dynamics damping="0.5" friction="0.1"/>
  </joint>
  <link name="LF_FOOT">
    <visual>
      <origin rpy="0 0 0" xyz="0 0.051053 0"/>
      <geometry>
        <mesh filename="package://qm_description/meshes/quadruped/b2w/foot.dae" scale="1 1 1"/>
      </geometry>
      <material name="orange"/>
    </visual>
    <collision>
      <origin rpy="0 0 0" xyz="0 0 0"/>
      <geometry>
        <sphere radius="0.10"/>
        <!-- cylinder radius="0.1125" length="0.1"/ -->
      </geometry>
    </collision>
    <inertial>
      <origin rpy="0 0 0" xyz="0 0.051053 0"/>
      <mass value="0.118"/>
      <inertia ixx="0.004121" ixy="6E-06" ixz="-4.8E-05" iyy="0.007776" iyz="7E-06" izz="0.004108"/>
      <!-- xacro:cylinder_inertia m="${foot_mass}" r="0.1125" h="0.1"/ -->
    </inertial>
  </link>
  <gazebo reference="LF_foot">
    <disableFixedJointLumping>true</disableFixedJointLumping>
  </gazebo>
  <gazebo reference="LF_hip">
    <mu1>0.2</mu1>
    <mu2>0.2</mu2>
    <material>Gazebo/DarkGrey</material>
  </gazebo>
  <gazebo reference="LF_thigh">
    <mu1>0.2</mu1>
    <mu2>0.2</mu2>
    <self_collide>0</self_collide>
    <material>Gazebo/DarkGrey</material>
    <kp value="1000000.0"/>
    <kd value="100.0"/>
  </gazebo>
  <gazebo reference="LF_calf">
    <mu1>0.6</mu1>
    <mu2>0.6</mu2>
    <self_collide>1</self_collide>
  </gazebo>
  <gazebo reference="LF_FOOT">
    <mu1>1.0</mu1>
    <mu2>1.0</mu2>
    <self_collide>1</self_collide>
    <material>Gazebo/DarkGrey</material>
    <kp value="1000000.0"/>
    <kd value="100.0"/>
  </gazebo>
  <transmission name="LF_HAA_tran">
    <type>transmission_interface/SimpleTransmission</type>
    <joint name="LF_HAA">
      <hardwareInterface>hardware_interface/EffortJointInterface</hardwareInterface>
    </joint>
    <actuator name="LF_HAA_motor">
      <hardwareInterface>hardware_interface/EffortJointInterface</hardwareInterface>
      <mechanicalReduction>1</mechanicalReduction>
    </actuator>
  </transmission>
  <transmission name="LF_HFE_tran">
    <type>transmission_interface/SimpleTransmission</type>
    <joint name="LF_HFE">
      <hardwareInterface>hardware_interface/EffortJointInterface</hardwareInterface>
    </joint>
    <actuator name="LF_HFE_motor">
      <hardwareInterface>hardware_interface/EffortJointInterface</hardwareInterface>
      <mechanicalReduction>1</mechanicalReduction>
    </actuator>
  </transmission>
  <transmission name="LF_KFE_tran">
    <type>transmission_interface/SimpleTransmission</type>
    <joint name="LF_KFE">
      <hardwareInterface>hardware_interface/EffortJointInterface</hardwareInterface>
    </joint>
    <actuator name="LF_KFE_motor">
      <hardwareInterface>hardware_interface/EffortJointInterface</hardwareInterface>
      <mechanicalReduction>1</mechanicalReduction>
    </actuator>
  </transmission>
  <transmission name="LF_tran">
    <type>transmission_interface/SimpleTransmission</type>
    <joint name="LF_foot">
      <hardwareInterface>hardware_interface/VelocityJointInterface</hardwareInterface>
    </joint>
    <actuator name="LF_foot_motor">
      <hardwareInterface>hardware_interface/VelocityJointInterface</hardwareInterface>
      <mechanicalReduction>1</mechanicalReduction>
    </actuator>
  </transmission>
  <joint name="LH_HAA" type="revolute">
    <origin rpy="0.2 0 0" xyz="-0.3285 0.072 0"/>
    <parent link="base"/>
    <child link="LH_hip"/>
    <axis xyz="1 0 0"/>
    <dynamics damping="0.2" friction="0"/>
    <limit effort="200" lower="-0.87" upper="0.87" velocity="23"/>
  </joint>
  <link name="LH_hip">
    <visual>
      <origin rpy="0 3.141592653589793 0" xyz="0 0 0"/>
      <geometry>
        <mesh filename="package://qm_description/meshes/quadruped/b2w/hip.dae" scale="1 1 1"/>
      </geometry>
      <material name="orange"/>
    </visual>
    <collision>
      <origin rpy="1.5707963267948966 0 0" xyz="0 0 0"/>
      <geometry>
        <cylinder length="0.05" radius="0.07"/>
      </geometry>
    </collision>
    <inertial>
      <origin rpy="0 0 0" xyz="0.009305 -0.010228 0.000264"/>
      <mass value="0.595"/>
      <inertia ixx="0.0026431" ixy="-0.00019234" ixz="6.76e-06" iyy="0.0046728" iyz="-7.16e-06" izz="0.0034208"/>
    </inertial>
  </link>
  <joint name="LH_HFE" type="revolute">
    <origin rpy="0 0 0" xyz="0 0.11973 0"/>
    <parent link="LH_hip"/>
    <child link="LH_thigh"/>
    <axis xyz="0 1 0"/>
    <dynamics damping="0.2" friction="0"/>
    <limit effort="200" lower="-94" upper="4.69" velocity="23"/>
    <pose>0 0 0 0 0 0</pose>
  </joint>
  <link name="LH_thigh">
    <visual>
      <origin rpy="0 0 0" xyz="0 0 0"/>
      <geometry>
        <mesh filename="package://qm_description/meshes/quadruped/b2w/thigh.dae" scale="1 1 1"/>
      </geometry>
      <material name="orange"/>
    </visual>
    <collision>
      <origin rpy="0 1.6707963267948966 0" xyz="-0.015 0 -0.16"/>
      <geometry>
        <box size="0.32 0.0455 0.054"/>
      </geometry>
    </collision>
    <collision>
      <origin rpy="1.5707963267948966 0 0" xyz="0 -0.008 0"/>
      <geometry>
        <cylinder length="0.08" radius="0.044"/>
      </geometry>
    </collision>
    <inertial>
      <origin rpy="0 0 0" xyz="-0.004346 -0.035797 -0.044921"/>
      <mass value="0.888"/>
      <inertia ixx="0.041718" ixy="0.00055623" ixz="-0.0022768" iyy="0.041071" iyz="0.005796" izz="0.0065677"/>
    </inertial>
  </link>
  <joint name="LH_KFE" type="revolute">
    <origin rpy="0 0 0" xyz="0 0 -0.32"/>
    <parent link="LH_thigh"/>
    <child link="LH_calf"/>
    <axis xyz="0 1 0"/>
    <dynamics damping="0.2" friction="0"/>
    <limit effort="320" lower="-2.82" upper="-0.43" velocity="14"/>
    <pose>0 0 0 0 0 0</pose>
  </joint>
  <link name="LH_calf">
    <visual>
      <origin rpy="0 0 0" xyz="0 0 0"/>
      <geometry>
        <mesh filename="package://qm_description/meshes/quadruped/b2w/calf.dae" scale="1 1 1"/>
      </geometry>
      <material name="orange"/>
    </visual>
    <collision>
      <origin rpy="0 1.5707963267948966 0" xyz="0.0 0 -0.175"/>
      <geometry>
        <box size="0.35 0.04 0.05"/>
      </geometry>
    </collision>
    <inertial>
      <origin rpy="0 0 0" xyz="0.006095 0.012046 -0.29122"/>
      <mass value="0.151"/>
      <inertia ixx="0.028133" ixy="0.00016307" ixz="-0.0010034" iyy="0.029251" iyz="0.0014765" izz="0.0028379"/>
    </inertial>
  </link>
  <joint dont_collapse="true" name="LH_foot" type="continuous">
    <origin rpy="0 0 0" xyz="0 0 -0.35"/>
    <parent link="LH_calf"/>
    <child link="LH_FOOT"/>
    <axis xyz="0 1 0"/>
    <limit effort="20" velocity="50"/>
    <dynamics damping="0.5" friction="0.1"/>
  </joint>
  <link name="LH_FOOT">
    <visual>
      <origin rpy="0 0 0" xyz="0 0.051053 0"/>
      <geometry>
        <mesh filename="package://qm_description/meshes/quadruped/b2w/foot.dae" scale="1 1 1"/>
      </geometry>
      <material name="orange"/>
    </visual>
    <collision>
      <origin rpy="0 0 0" xyz="0 0 0"/>
      <geometry>
        <sphere radius="0.10"/>
        <!-- cylinder radius="0.1125" length="0.1"/ -->
      </geometry>
    </collision>
    <inertial>
      <origin rpy="0 0 0" xyz="0 0.051053 0"/>
      <mass value="0.118"/>
      <inertia ixx="0.004121" ixy="6E-06" ixz="-4.8E-05" iyy="0.007776" iyz="7E-06" izz="0.004108"/>
      <!-- xacro:cylinder_inertia m="${foot_mass}" r="0.1125" h="0.1"/ -->
    </inertial>
  </link>
  <gazebo reference="LH_foot">
    <disableFixedJointLumping>true</disableFixedJointLumping>
  </gazebo>
  <gazebo reference="LH_hip">
    <mu1>0.2</mu1>
    <mu2>0.2</mu2>
    <material>Gazebo/DarkGrey</material>
  </gazebo>
  <gazebo reference="LH_thigh">
    <mu1>0.2</mu1>
    <mu2>0.2</mu2>
    <self_collide>0</self_collide>
    <material>Gazebo/DarkGrey</material>
    <kp value="1000000.0"/>
    <kd value="100.0"/>
  </gazebo>
  <gazebo reference="LH_calf">
    <mu1>0.6</mu1>
    <mu2>0.6</mu2>
    <self_collide>1</self_collide>
  </gazebo>
  <gazebo reference="LH_FOOT">
    <mu1>1.0</mu1>
    <mu2>1.0</mu2>
    <self_collide>1</self_collide>
    <material>Gazebo/DarkGrey</material>
    <kp value="1000000.0"/>
    <kd value="100.0"/>
  </gazebo>
  <transmission name="LH_HAA_tran">
    <type>transmission_interface/SimpleTransmission</type>
    <joint name="LH_HAA">
      <hardwareInterface>hardware_interface/EffortJointInterface</hardwareInterface>
    </joint>
    <actuator name="LH_HAA_motor">
      <hardwareInterface>hardware_interface/EffortJointInterface</hardwareInterface>
      <mechanicalReduction>1</mechanicalReduction>
    </actuator>
  </transmission>
  <transmission name="LH_HFE_tran">
    <type>transmission_interface/SimpleTransmission</type>
    <joint name="LH_HFE">
      <hardwareInterface>hardware_interface/EffortJointInterface</hardwareInterface>
    </joint>
    <actuator name="LH_HFE_motor">
      <hardwareInterface>hardware_interface/EffortJointInterface</hardwareInterface>
      <mechanicalReduction>1</mechanicalReduction>
    </actuator>
  </transmission>
  <transmission name="LH_KFE_tran">
    <type>transmission_interface/SimpleTransmission</type>
    <joint name="LH_KFE">
      <hardwareInterface>hardware_interface/EffortJointInterface</hardwareInterface>
    </joint>
    <actuator name="LH_KFE_motor">
      <hardwareInterface>hardware_interface/EffortJointInterface</hardwareInterface>
      <mechanicalReduction>1</mechanicalReduction>
    </actuator>
  </transmission>
  <transmission name="LH_tran">
    <type>transmission_interface/SimpleTransmission</type>
    <joint name="LH_foot">
      <hardwareInterface>hardware_interface/VelocityJointInterface</hardwareInterface>
    </joint>
    <actuator name="LH_foot_motor">
      <hardwareInterface>hardware_interface/VelocityJointInterface</hardwareInterface>
      <mechanicalReduction>1</mechanicalReduction>
    </actuator>
  </transmission>
  <joint name="RF_HAA" type="revolute">
    <origin rpy="-0.2 0 0" xyz="0.3285 -0.072 0"/>
    <parent link="base"/>
    <child link="RF_hip"/>
    <axis xyz="1 0 0"/>
    <dynamics damping="0.2" friction="0"/>
    <limit effort="200" lower="-0.87" upper="0.87" velocity="23"/>
  </joint>
  <link name="RF_hip">
    <visual>
      <origin rpy="3.141592653589793 0 0" xyz="0 0 0"/>
      <geometry>
        <mesh filename="package://qm_description/meshes/quadruped/b2w/hip.dae" scale="1 1 1"/>
      </geometry>
      <material name="orange"/>
    </visual>
    <collision>
      <origin rpy="1.5707963267948966 0 0" xyz="0 0 0"/>
      <geometry>
        <cylinder length="0.05" radius="0.07"/>
      </geometry>
    </collision>
    <inertial>
      <origin rpy="0 0 0" xyz="-0.009305 0.010228 0.000264"/>
      <mass value="0.595"/>
      <inertia ixx="0.0026431" ixy="-0.00019234" ixz="-6.76e-06" iyy="0.0046728" iyz="7.16e-06" izz="0.0034208"/>
    </inertial>
  </link>
  <joint name="RF_HFE" type="revolute">
    <origin rpy="0 0 0" xyz="0 -0.11973 0"/>
    <parent link="RF_hip"/>
    <child link="RF_thigh"/>
    <axis xyz="0 1 0"/>
    <dynamics damping="0.2" friction="0"/>
    <limit effort="200" lower="-94" upper="4.69" velocity="23"/>
    <pose>0 0 0 0 0 0</pose>
  </joint>
  <link name="RF_thigh">
    <visual>
      <origin rpy="0 0 0" xyz="0 0 0"/>
      <geometry>
        <mesh filename="package://qm_description/meshes/quadruped/b2w/thigh_mirror.dae" scale="1 1 1"/>
      </geometry>
      <material name="orange"/>
    </visual>
    <collision>
      <origin rpy="0 1.6707963267948966 0" xyz="-0.015 0 -0.16"/>
      <geometry>
        <box size="0.32 0.0455 0.054"/>
      </geometry>
    </collision>
    <collision>
      <origin rpy="1.5707963267948966 0 0" xyz="0 0.008 0"/>
      <geometry>
        <cylinder length="0.08" radius="0.044"/>
      </geometry>
    </collision>
    <inertial>
      <origin rpy="0 0 0" xyz="-0.004346 0.035797 -0.044921"/>
      <mass value="0.888"/>
      <inertia ixx="0.041718" ixy="-0.00055623" ixz="-0.0022768" iyy="0.041071" iyz="-0.005796" izz="0.0065677"/>
    </inertial>
  </link>
  <joint name="RF_KFE" type="revolute">
    <origin rpy="0 0 0" xyz="0 0 -0.32"/>
    <parent link="RF_thigh"/>
    <child link="RF_calf"/>
    <axis xyz="0 1 0"/>
    <dynamics damping="0.2" friction="0"/>
    <limit effort="320" lower="-2.82" upper="-0.43" velocity="14"/>
    <pose>0 0 0 0 0 0</pose>
  </joint>
  <link name="RF_calf">
    <visual>
      <origin rpy="0 0 0" xyz="0 0 0"/>
      <geometry>
        <mesh filename="package://qm_description/meshes/quadruped/b2w/calf_mirror.dae" scale="1 1 1"/>
      </geometry>
      <material name="orange"/>
    </visual>
    <collision>
      <origin rpy="0 1.5707963267948966 0" xyz="0.0 0 -0.175"/>
      <geometry>
        <box size="0.35 0.04 0.05"/>
      </geometry>
    </collision>
    <inertial>
      <origin rpy="0 0 0" xyz="0.006095 0.012046 -0.29122"/>
      <mass value="0.151"/>
      <inertia ixx="0.028133" ixy="0.00016307" ixz="-0.0010034" iyy="0.029251" iyz="0.0014765" izz="0.0028379"/>
    </inertial>
  </link>
  <joint dont_collapse="true" name="RF_foot" type="continuous">
    <origin rpy="0 0 0" xyz="0 0 -0.35"/>
    <parent link="RF_calf"/>
    <child link="RF_FOOT"/>
    <axis xyz="0 1 0"/>
    <limit effort="20" velocity="50"/>
    <dynamics damping="0.5" friction="0.1"/>
  </joint>
  <link name="RF_FOOT">
    <visual>
      <origin rpy="0 0 0" xyz="0 -0.051053 0"/>
      <geometry>
        <mesh filename="package://qm_description/meshes/quadruped/b2w/foot_mirror.dae" scale="1 1 1"/>
      </geometry>
      <material name="orange"/>
    </visual>
    <collision>
      <origin rpy="0 0 0" xyz="0 0 0"/>
      <geometry>
        <sphere radius="0.10"/>
        <!-- cylinder radius="0.1125" length="0.1"/ -->
      </geometry>
    </collision>
    <inertial>
      <origin rpy="0 0 0" xyz="0 -0.051053 0"/>
      <mass value="0.118"/>
      <inertia ixx="0.004121" ixy="6E-06" ixz="-4.8E-05" iyy="0.007776" iyz="7E-06" izz="0.004108"/>
      <!-- xacro:cylinder_inertia m="${foot_mass}" r="0.1125" h="0.1"/ -->
    </inertial>
  </link>
  <gazebo reference="RF_foot">
    <disableFixedJointLumping>true</disableFixedJointLumping>
  </gazebo>
  <gazebo reference="RF_hip">
    <mu1>0.2</mu1>
    <mu2>0.2</mu2>
    <material>Gazebo/DarkGrey</material>
  </gazebo>
  <gazebo reference="RF_thigh">
    <mu1>0.2</mu1>
    <mu2>0.2</mu2>
    <self_collide>0</self_collide>
    <material>Gazebo/DarkGrey</material>
    <kp value="1000000.0"/>
    <kd value="100.0"/>
  </gazebo>
  <gazebo reference="RF_calf">
    <mu1>0.6</mu1>
    <mu2>0.6</mu2>
    <self_collide>1</self_collide>
  </gazebo>
  <gazebo reference="RF_FOOT">
    <mu1>1.0</mu1>
    <mu2>1.0</mu2>
    <self_collide>1</self_collide>
    <material>Gazebo/DarkGrey</material>
    <kp value="1000000.0"/>
    <kd value="100.0"/>
  </gazebo>
  <transmission name="RF_HAA_tran">
    <type>transmission_interface/SimpleTransmission</type>
    <joint name="RF_HAA">
      <hardwareInterface>hardware_interface/EffortJointInterface</hardwareInterface>
    </joint>
    <actuator name="RF_HAA_motor">
      <hardwareInterface>hardware_interface/EffortJointInterface</hardwareInterface>
      <mechanicalReduction>1</mechanicalReduction>
    </actuator>
  </transmission>
  <transmission name="RF_HFE_tran">
    <type>transmission_interface/SimpleTransmission</type>
    <joint name="RF_HFE">
      <hardwareInterface>hardware_interface/EffortJointInterface</hardwareInterface>
    </joint>
    <actuator name="RF_HFE_motor">
      <hardwareInterface>hardware_interface/EffortJointInterface</hardwareInterface>
      <mechanicalReduction>1</mechanicalReduction>
    </actuator>
  </transmission>
  <transmission name="RF_KFE_tran">
    <type>transmission_interface/SimpleTransmission</type>
    <joint name="RF_KFE">
      <hardwareInterface>hardware_interface/EffortJointInterface</hardwareInterface>
    </joint>
    <actuator name="RF_KFE_motor">
      <hardwareInterface>hardware_interface/EffortJointInterface</hardwareInterface>
      <mechanicalReduction>1</mechanicalReduction>
    </actuator>
  </transmission>
  <transmission name="RF_tran">
    <type>transmission_interface/SimpleTransmission</type>
    <joint name="RF_foot">
      <hardwareInterface>hardware_interface/VelocityJointInterface</hardwareInterface>
    </joint>
    <actuator name="RF_foot_motor">
      <hardwareInterface>hardware_interface/VelocityJointInterface</hardwareInterface>
      <mechanicalReduction>1</mechanicalReduction>
    </actuator>
  </transmission>
  <joint name="RH_HAA" type="revolute">
    <origin rpy="-0.2 0 0" xyz="-0.3285 -0.072 0"/>
    <parent link="base"/>
    <child link="RH_hip"/>
    <axis xyz="1 0 0"/>
    <dynamics damping="0.2" friction="0"/>
    <limit effort="200" lower="-0.87" upper="0.87" velocity="23"/>
  </joint>
  <link name="RH_hip">
    <visual>
      <origin rpy="3.141592653589793 3.141592653589793 0" xyz="0 0 0"/>
      <geometry>
        <mesh filename="package://qm_description/meshes/quadruped/b2w/hip.dae" scale="1 1 1"/>
      </geometry>
      <material name="orange"/>
    </visual>
    <collision>
      <origin rpy="1.5707963267948966 0 0" xyz="0 0 0"/>
      <geometry>
        <cylinder length="0.05" radius="0.07"/>
      </geometry>
    </collision>
    <inertial>
      <origin rpy="0 0 0" xyz="0.009305 0.010228 0.000264"/>
      <mass value="0.595"/>
      <inertia ixx="0.0026431" ixy="0.00019234" ixz="6.76e-06" iyy="0.0046728" iyz="7.16e-06" izz="0.0034208"/>
    </inertial>
  </link>
  <joint name="RH_HFE" type="revolute">
    <origin rpy="0 0 0" xyz="0 -0.11973 0"/>
    <parent link="RH_hip"/>
    <child link="RH_thigh"/>
    <axis xyz="0 1 0"/>
    <dynamics damping="0.2" friction="0"/>
    <limit effort="200" lower="-94" upper="4.69" velocity="23"/>
    <pose>0 0 0 0 0 0</pose>
  </joint>
  <link name="RH_thigh">
    <visual>
      <origin rpy="0 0 0" xyz="0 0 0"/>
      <geometry>
        <mesh filename="package://qm_description/meshes/quadruped/b2w/thigh_mirror.dae" scale="1 1 1"/>
      </geometry>
      <material name="orange"/>
    </visual>
    <collision>
      <origin rpy="0 1.6707963267948966 0" xyz="-0.015 0 -0.16"/>
      <geometry>
        <box size="0.32 0.0455 0.054"/>
      </geometry>
    </collision>
    <collision>
      <origin rpy="1.5707963267948966 0 0" xyz="0 0.008 0"/>
      <geometry>
        <cylinder length="0.08" radius="0.044"/>
      </geometry>
    </collision>
    <inertial>
      <origin rpy="0 0 0" xyz="-0.004346 0.035797 -0.044921"/>
      <mass value="0.888"/>
      <inertia ixx="0.041718" ixy="-0.00055623" ixz="-0.0022768" iyy="0.041071" iyz="-0.005796" izz="0.0065677"/>
    </inertial>
  </link>
  <joint name="RH_KFE" type="revolute">
    <origin rpy="0 0 0" xyz="0 0 -0.32"/>
    <parent link="RH_thigh"/>
    <child link="RH_calf"/>
    <axis xyz="0 1 0"/>
    <dynamics damping="0.2" friction="0"/>
    <limit effort="320" lower="-2.82" upper="-0.43" velocity="14"/>
    <pose>0 0 0 0 0 0</pose>
  </joint>
  <link name="RH_calf">
    <visual>
      <origin rpy="0 0 0" xyz="0 0 0"/>
      <geometry>
        <mesh filename="package://qm_description/meshes/quadruped/b2w/calf_mirror.dae" scale="1 1 1"/>
      </geometry>
      <material name="orange"/>
    </visual>
    <collision>
      <origin rpy="0 1.5707963267948966 0" xyz="0.0 0 -0.175"/>
      <geometry>
        <box size="0.35 0.04 0.05"/>
      </geometry>
    </collision>
    <inertial>
      <origin rpy="0 0 0" xyz="0.006095 0.012046 -0.29122"/>
      <mass value="0.151"/>
      <inertia ixx="0.028133" ixy="0.00016307" ixz="-0.0010034" iyy="0.029251" iyz="0.0014765" izz="0.0028379"/>
    </inertial>
  </link>
  <joint dont_collapse="true" name="RH_foot" type="continuous">
    <origin rpy="0 0 0" xyz="0 0 -0.35"/>
    <parent link="RH_calf"/>
    <child link="RH_FOOT"/>
    <axis xyz="0 1 0"/>
    <limit effort="20" velocity="50"/>
    <dynamics damping="0.5" friction="0.1"/>
  </joint>
  <link name="RH_FOOT">
    <visual>
      <origin rpy="0 0 0" xyz="0 -0.051053 0"/>
      <geometry>
        <mesh filename="package://qm_description/meshes/quadruped/b2w/foot_mirror.dae" scale="1 1 1"/>
      </geometry>
      <material name="orange"/>
    </visual>
    <collision>
      <origin rpy="0 0 0" xyz="0 0 0"/>
      <geometry>
        <sphere radius="0.10"/>
        <!-- cylinder radius="0.1125" length="0.1"/ -->
      </geometry>
    </collision>
    <inertial>
      <origin rpy="0 0 0" xyz="0 -0.051053 0"/>
      <mass value="0.118"/>
      <inertia ixx="0.004121" ixy="6E-06" ixz="-4.8E-05" iyy="0.007776" iyz="7E-06" izz="0.004108"/>
      <!-- xacro:cylinder_inertia m="${foot_mass}" r="0.1125" h="0.1"/ -->
    </inertial>
  </link>
  <gazebo reference="RH_foot">
    <disableFixedJointLumping>true</disableFixedJointLumping>
  </gazebo>
  <gazebo reference="RH_hip">
    <mu1>0.2</mu1>
    <mu2>0.2</mu2>
    <material>Gazebo/DarkGrey</material>
  </gazebo>
  <gazebo reference="RH_thigh">
    <mu1>0.2</mu1>
    <mu2>0.2</mu2>
    <self_collide>0</self_collide>
    <material>Gazebo/DarkGrey</material>
    <kp value="1000000.0"/>
    <kd value="100.0"/>
  </gazebo>
  <gazebo reference="RH_calf">
    <mu1>0.6</mu1>
    <mu2>0.6</mu2>
    <self_collide>1</self_collide>
  </gazebo>
  <gazebo reference="RH_FOOT">
    <mu1>1.0</mu1>
    <mu2>1.0</mu2>
    <self_collide>1</self_collide>
    <material>Gazebo/DarkGrey</material>
    <kp value="1000000.0"/>
    <kd value="100.0"/>
  </gazebo>
  <transmission name="RH_HAA_tran">
    <type>transmission_interface/SimpleTransmission</type>
    <joint name="RH_HAA">
      <hardwareInterface>hardware_interface/EffortJointInterface</hardwareInterface>
    </joint>
    <actuator name="RH_HAA_motor">
      <hardwareInterface>hardware_interface/EffortJointInterface</hardwareInterface>
      <mechanicalReduction>1</mechanicalReduction>
    </actuator>
  </transmission>
  <transmission name="RH_HFE_tran">
    <type>transmission_interface/SimpleTransmission</type>
    <joint name="RH_HFE">
      <hardwareInterface>hardware_interface/EffortJointInterface</hardwareInterface>
    </joint>
    <actuator name="RH_HFE_motor">
      <hardwareInterface>hardware_interface/EffortJointInterface</hardwareInterface>
      <mechanicalReduction>1</mechanicalReduction>
    </actuator>
  </transmission>
  <transmission name="RH_KFE_tran">
    <type>transmission_interface/SimpleTransmission</type>
    <joint name="RH_KFE">
      <hardwareInterface>hardware_interface/EffortJointInterface</hardwareInterface>
    </joint>
    <actuator name="RH_KFE_motor">
      <hardwareInterface>hardware_interface/EffortJointInterface</hardwareInterface>
      <mechanicalReduction>1</mechanicalReduction>
    </actuator>
  </transmission>
  <transmission name="RH_tran">
    <type>transmission_interface/SimpleTransmission</type>
    <joint name="RH_foot">
      <hardwareInterface>hardware_interface/VelocityJointInterface</hardwareInterface>
    </joint>
    <actuator name="RH_foot_motor">
      <hardwareInterface>hardware_interface/VelocityJointInterface</hardwareInterface>
      <mechanicalReduction>1</mechanicalReduction>
    </actuator>
  </transmission>
  <!-- Z1 manipulator -->
  <joint name="manipulator_joint" type="fixed">
    <origin rpy="0 0 0" xyz="0 0 0.075"/>
    <parent link="base"/>
    <child link="z1_link_0"/>
  </joint>
  <link name="z1_link_0">
    <visual>
      <origin rpy="0 0 0" xyz="0 0 0"/>
      <geometry>
        <mesh filename="package://qm_description/meshes/manipulator/z1_Link00.stl" scale="1 1 1"/>
      </geometry>
      <material name="silver"/>
    </visual>
    <collision>
      <geometry>
        <cylinder length="0.051" radius="0.0325"/>
      </geometry>
      <origin rpy="0 0 0" xyz="0 0 0.0255"/>
    </collision>
    <inertial>
      <origin rpy="0 0 0" xyz="-0.00334984 -0.00013615 0.02495843"/>
      <mass value="0.27247481"/>
      <inertia ixx="0.00037937" ixy="-3.5e-07" ixz="-1.037e-05" iyy="0.00041521" iyz="-9.9e-07" izz="0.00053066"/>
    </inertial>
  </link>
  <joint name="z1_joint_1" type="revolute">
    <origin rpy="0 0 0" xyz="0 0 0.0585"/>
    <parent link="z1_link_0"/>
    <child link="z1_link_1"/>
    <axis xyz="0 0 1"/>
    <dynamics damping="1.0" friction="1.0"/>
    <limit effort="30.0" lower="-2.6179938779914944" upper="2.6179938779914944" velocity="3.1415"/>
  </joint>
  <transmission name="z1_joint_1_trans">
    <type>transmission_interface/SimpleTransmission</type>
    <joint name="z1_joint_1">
      <hardwareInterface>hardware_interface/EffortJointInterface</hardwareInterface>
    </joint>
    <actuator name="z1_joint_1_actuator">
      <hardwareInterface>hardware_interface/EffortJointInterface</hardwareInterface>
      <mechanicalReduction>1</mechanicalReduction>
    </actuator>
  </transmission>
  <gazebo>
    <plugin filename="libgazebo_ros_ft_sensor.so" name="ft_sensor">
      <updateRate>30.0</updateRate>
      <topicName>z1_joint_1_ft_sensor_topic</topicName>
      <jointName>z1_joint_1</jointName>
    </plugin>
  </gazebo>
  <link name="z1_link_1">
    <visual>
      <origin rpy="0 0 0" xyz="0 0 0"/>
      <geometry>
        <mesh filename="package://qm_description/meshes/manipulator/z1_Link01.stl" scale="1 1 1"/>
      </geometry>
      <material name="silver"/>
    </visual>
    <collision>
      <geometry>
        <cylinder length="0.102" radius="0.0325"/>
      </geometry>
      <origin rpy="0 0 0" xyz="0 0 0"/>
    </collision>
    <inertial>
      <origin rpy="0 0 0" xyz="2.47e-06 -0.00025198 0.02317169"/>
      <mass value="0.37332551"/>
      <inertia ixx="0.00128328" ixy="-6e-08" ixz="-4e-07" iyy="0.00071931" iyz="5e-07" izz="0.00083936"/>
    </inertial>
  </link>
  <joint name="z1_joint_2" type="revolute">
    <origin rpy="0 0 0" xyz="0 0 0.045"/>
    <parent link="z1_link_1"/>
    <child link="z1_link_2"/>
    <axis xyz="0 1 0"/>
    <dynamics damping="2.0" friction="2.0"/>
    <limit effort="60.0" lower="0.0" upper="2.9670597283903604" velocity="3.1415"/>
  </joint>
  <transmission name="z1_joint_2_trans">
    <type>transmission_interface/SimpleTransmission</type>
    <joint name="z1_joint_2">
      <hardwareInterface>hardware_interface/EffortJointInterface</hardwareInterface>
    </joint>
    <actuator name="z1_joint_2_actuator">
      <hardwareInterface>hardware_interface/EffortJointInterface</hardwareInterface>
      <mechanicalReduction>1</mechanicalReduction>
    </actuator>
  </transmission>
  <gazebo>
    <plugin filename="libgazebo_ros_ft_sensor.so" name="ft_sensor">
      <updateRate>30.0</updateRate>
      <topicName>z1_joint_2_ft_sensor_topic</topicName>
      <jointName>z1_joint_2</jointName>
    </plugin>
  </gazebo>
  <link name="z1_link_2">
    <visual>
      <origin rpy="0 0 0" xyz="0 0 0"/>
      <geometry>
        <mesh filename="package://qm_description/meshes/manipulator/z1_Link02.stl" scale="1 1 1"/>
      </geometry>
      <material name="silver"/>
    </visual>
    <collision>
      <geometry>
        <cylinder length="0.102" radius="0.0325"/>
      </geometry>
      <origin rpy="1.5707963267948966 0 0" xyz="0 0 0"/>
    </collision>
    <collision>
      <geometry>
        <cylinder length="0.235" radius="0.0225"/>
      </geometry>
      <origin rpy="0 1.5707963267948966 0" xyz="-0.16249999999999998 0 0"/>
    </collision>
    <collision>
      <geometry>
        <cylinder length="0.051" radius="0.0325"/>
      </geometry>
      <origin rpy="1.5707963267948966 0 0" xyz="-0.35 0 0"/>
    </collision>
    <inertial>
      <origin rpy="0 0 0" xyz="-0.11012601 0.00240029 0.00158266"/>
      <mass value="0.59132258"/>
      <inertia ixx="0.00102138" ixy="0.00062358" ixz="5.13e-06" iyy="0.02429457" iyz="-2.1e-06" izz="0.02466114"/>
    </inertial>
  </link>
  <joint name="z1_joint_3" type="revolute">
    <origin rpy="0 0 0" xyz="-0.35 0 0"/>
    <parent link="z1_link_2"/>
    <child link="z1_link_3"/>
    <axis xyz="0 1 0"/>
    <dynamics damping="1.0" friction="1.0"/>
    <limit effort="30.0" lower="-2.8797932657906435" upper="0.0" velocity="3.1415"/>
  </joint>
  <transmission name="z1_joint_3_trans">
    <type>transmission_interface/SimpleTransmission</type>
    <joint name="z1_joint_3">
      <hardwareInterface>hardware_interface/EffortJointInterface</hardwareInterface>
    </joint>
    <actuator name="z1_joint_3_actuator">
      <hardwareInterface>hardware_interface/EffortJointInterface</hardwareInterface>
      <mechanicalReduction>1</mechanicalReduction>
    </actuator>
  </transmission>
  <gazebo>
    <plugin filename="libgazebo_ros_ft_sensor.so" name="ft_sensor">
      <updateRate>30.0</updateRate>
      <topicName>z1_joint_3_ft_sensor_topic</topicName>
      <jointName>z1_joint_3</jointName>
    </plugin>
  </gazebo>
  <link name="z1_link_3">
    <visual>
      <origin rpy="0 0 0" xyz="0 0 0"/>
      <geometry>
        <mesh filename="package://qm_description/meshes/manipulator/z1_Link03.stl" scale="1 1 1"/>
      </geometry>
      <material name="silver"/>
    </visual>
    <collision>
      <geometry>
        <cylinder length="0.116" radius="0.02"/>
      </geometry>
      <origin rpy="0 1.5707963267948966 0" xyz="0.128 0 0.055"/>
    </collision>
    <collision>
      <geometry>
        <cylinder length="0.059" radius="0.0325"/>
      </geometry>
      <origin rpy="0 1.5707963267948966 1.5707963267948966" xyz="0.2205 0 0.055"/>
    </collision>
    <inertial>
      <origin rpy="0 0 0" xyz="0.10609208 -0.00541815 0.03476383"/>
      <mass value="0.43940874"/>
      <inertia ixx="0.00108061" ixy="-8.669e-05" ixz="-0.00208102" iyy="0.00954238" iyz="-1.332e-05" izz="0.00886621"/>
    </inertial>
  </link>
  <joint name="z1_joint_4" type="revolute">
    <origin rpy="0 0 0" xyz="0.218 0 0.057"/>
    <parent link="z1_link_3"/>
    <child link="z1_link_4"/>
    <axis xyz="0 1 0"/>
    <dynamics damping="1.0" friction="1.0"/>
    <limit effort="30.0" lower="-1.5184364492350666" upper="1.5184364492350666" velocity="3.1415"/>
  </joint>
  <transmission name="z1_joint_4_trans">
    <type>transmission_interface/SimpleTransmission</type>
    <joint name="z1_joint_4">
      <hardwareInterface>hardware_interface/EffortJointInterface</hardwareInterface>
    </joint>
    <actuator name="z1_joint_4_actuator">
      <hardwareInterface>hardware_interface/EffortJointInterface</hardwareInterface>
      <mechanicalReduction>1</mechanicalReduction>
    </actuator>
  </transmission>
  <gazebo>
    <plugin filename="libgazebo_ros_ft_sensor.so" name="ft_sensor">
      <updateRate>30.0</updateRate>
      <topicName>z1_joint_4_ft_sensor_topic</topicName>
      <jointName>z1_joint_4</jointName>
    </plugin>
  </gazebo>
  <link name="z1_link_4">
    <visual>
      <origin rpy="0 0 0" xyz="0 0 0"/>
      <geometry>
        <mesh filename="package://qm_description/meshes/manipulator/z1_Link04.stl" scale="1 1 1"/>
      </geometry>
      <material name="silver"/>
    </visual>
    <collision>
      <geometry>
        <cylinder length="0.067" radius="0.0325"/>
      </geometry>
      <origin rpy="0 0 0" xyz="0.072 0 0"/>
    </collision>
    <inertial>
      <origin rpy="0 0 0" xyz="0.04366681 0.00364738 -0.00170192"/>
      <mass value="0.26404563"/>
      <inertia ixx="0.00031576" ixy="8.13e-05" ixz="4.091e-05" iyy="0.00092996" iyz="-5.96e-06" izz="0.00097912"/>
    </inertial>
  </link>
  <joint name="z1_joint_5" type="revolute">
    <origin rpy="0 0 0" xyz="0.07 0.0 0.0"/>
    <parent link="z1_link_4"/>
    <child link="z1_link_5"/>
    <axis xyz="0 0 1"/>
    <dynamics damping="1.0" friction="1.0"/>
    <limit effort="30.0" lower="-1.3439035240356338" upper="1.3439035240356338" velocity="3.1415"/>
  </joint>
  <transmission name="z1_joint_5_trans">
    <type>transmission_interface/SimpleTransmission</type>
    <joint name="z1_joint_5">
      <hardwareInterface>hardware_interface/EffortJointInterface</hardwareInterface>
    </joint>
    <actuator name="z1_joint_5_actuator">
      <hardwareInterface>hardware_interface/EffortJointInterface</hardwareInterface>
      <mechanicalReduction>1</mechanicalReduction>
    </actuator>
  </transmission>
  <gazebo>
    <plugin filename="libgazebo_ros_ft_sensor.so" name="ft_sensor">
      <updateRate>30.0</updateRate>
      <topicName>z1_joint_5_ft_sensor_topic</topicName>
      <jointName>z1_joint_5</jointName>
    </plugin>
  </gazebo>
  <link name="z1_link_5">
    <visual>
      <origin rpy="0 0 0" xyz="0 0 0"/>
      <geometry>
        <mesh filename="package://qm_description/meshes/manipulator/z1_Link05.stl" scale="1 1 1"/>
      </geometry>
      <material name="silver"/>
    </visual>
    <inertial>
      <origin rpy="0 0 0" xyz="0.03121533 0.0 0.00646316"/>
      <mass value="0.18938492"/>
      <inertia ixx="0.00017605" ixy="4e-07" ixz="5.689e-05" iyy="0.00055896" iyz="-1.3e-07" izz="0.0005386"/>
    </inertial>
  </link>
  <joint name="z1_joint_6" type="revolute">
    <origin rpy="0 0 0" xyz="0.0492 0.0 0.0"/>
    <parent link="z1_link_5"/>
    <child link="z1_link_6"/>
    <axis xyz="1 0 0"/>
    <dynamics damping="1.0" friction="1.0"/>
    <limit effort="30.0" lower="-2.792526803190927" upper="2.792526803190927" velocity="3.1415"/>
  </joint>
  <transmission name="z1_joint_6_trans">
    <type>transmission_interface/SimpleTransmission</type>
    <joint name="z1_joint_6">
      <hardwareInterface>hardware_interface/EffortJointInterface</hardwareInterface>
    </joint>
    <actuator name="z1_joint_6_actuator">
      <hardwareInterface>hardware_interface/EffortJointInterface</hardwareInterface>
      <mechanicalReduction>1</mechanicalReduction>
    </actuator>
  </transmission>
  <gazebo>
    <plugin filename="libgazebo_ros_ft_sensor.so" name="ft_sensor">
      <updateRate>30.0</updateRate>
      <topicName>z1_joint_6_ft_sensor_topic</topicName>
      <jointName>z1_joint_6</jointName>
    </plugin>
  </gazebo>
  <link name="z1_link_6">
    <visual>
      <origin rpy="0 0 0" xyz="0 0 0"/>
      <geometry>
        <mesh filename="package://qm_description/meshes/manipulator/z1_Link06.stl" scale="1 1 1"/>
      </geometry>
      <material name="silver"/>
    </visual>
    <collision>
      <geometry>
        <cylinder length="0.051" radius="0.0325"/>
      </geometry>
      <origin rpy="0 1.5707963267948966 0" xyz="0.0255 0 0"/>
    </collision>
    <inertial>
      <origin rpy="0 0 0" xyz="0.0241569 -0.00017355 -0.00143876"/>
      <mass value="0.18875807"/>
      <inertia ixx="0.00018328" ixy="1.22e-06" ixz="5.4e-07" iyy="0.0001475" iyz="8e-08" izz="0.0001468"/>
    </inertial>
  </link>
  <joint name="gripperStator" type="fixed">
    <origin rpy="0 0 0" xyz="0.051 0.0 0.0"/>
    <parent link="z1_link_6"/>
    <child link="gripperStator"/>
  </joint>
  <link name="gripperStator">
    <visual>
      <geometry>
        <mesh filename="package://qm_description/meshes/manipulator/z1_GripperStator.stl" scale="1 1 1"/>
      </geometry>
      <material name="black"/>
    </visual>
    <collision>
      <geometry>
        <mesh filename="package://qm_description/meshes/manipulator/z1_GripperStator.stl" scale="1 1 1"/>
      </geometry>
      <material name="green"/>
    </collision>
    <inertial>
      <origin rpy="0 0 0" xyz="0.04764427 -0.00035819 -0.00249162"/>
      <mass value="0.52603655"/>
      <inertia ixx="0.00038683" ixy="-3.59e-06" ixz="7.662e-05" iyy="0.00068614" iyz="2.09e-06" izz="0.00066293"/>
    </inertial>
  </link>
  <!-- TODO Change to revolute once controller is programmed -->
  <joint name="z1_joint_Gripper" type="revolute">
    <origin rpy="0 0 0" xyz="0.049 0.0 0"/>
    <parent link="gripperStator"/>
    <child link="gripperMover"/>
    <axis xyz="0 1 0"/>
    <dynamics damping="1.0" friction="1.0"/>
    <limit effort="30.0" lower="-1.5707963267948966" upper="0.0" velocity="3.1415"/>
  </joint>
  <transmission name="z1_joint_Gripper_trans">
    <type>transmission_interface/SimpleTransmission</type>
    <joint name="z1_joint_Gripper">
      <hardwareInterface>hardware_interface/EffortJointInterface</hardwareInterface>
    </joint>
    <actuator name="z1_joint_Gripper_motor">
      <mechanicalReduction>1</mechanicalReduction>
    </actuator>
  </transmission>
  <!-- <gazebo>
            <plugin name="gripper_position_controller" filename="libgazebo_ros_control_select_joints.so">
                <robotNamespace>/</robotNamespace>
                <joints>z1_joint_Gripper</joints>
            </plugin>
        </gazebo> -->
  <link name="gripperMover">
    <visual>
      <geometry>
        <mesh filename="package://qm_description/meshes/manipulator/z1_GripperMover.stl" scale="1 1 1"/>
      </geometry>
      <material name="black"/>
    </visual>
    <collision>
      <geometry>
        <mesh filename="package://qm_description/meshes/manipulator/z1_GripperMover.stl" scale="1 1 1"/>
      </geometry>
      <material name="green"/>
    </collision>
    <inertial>
      <origin rpy="0 0 0" xyz="0.01320633 0.00476708 0.00380534"/>
      <mass value="0.17621302"/>
      <inertia ixx="0.00017716" ixy="1.683e-05" ixz="-1.786e-05" iyy="0.00026787" iyz="2.62e-06" izz="0.00035728"/>
    </inertial>
  </link>
  <link name="z1_end_effector">
    <!-- <visual>
                <geometry>
                    <sphere radius="0.01"/>
                </geometry>
                <material name="red"/>
            </visual>
            <inertial>
                <mass value="0.0"/>
                <inertia ixx="0.0" ixy="0.0" ixz="0.0" iyy="0.0" iyz="0.0" izz="0.0"/>
            </inertial>
            <collision>
                <geometry>
                    <sphere radius="0.01"/>
                </geometry>
                <surface>
                    <contact>
                        <collide_bitmask>0</collide_bitmask>
                    </contact>
                </surface>
            </collision> -->
  </link>
  <joint name="z1_joint_end_effector" type="fixed">
    <origin rpy="0 0 0" xyz="0.135 0 0"/>
    <parent link="gripperStator"/>
    <child link="z1_end_effector"/>
  </joint>
  <!-- ros_control plugin -->
  <gazebo>
    <plugin filename="liblegged_hw_sim.so" name="gazebo_ros_control">
      <robotNamespace>/</robotNamespace>
      <robotParam>legged_robot_description</robotParam>
      <robotSimType>legged_gazebo/LeggedHWSim</robotSimType>
    </plugin>
  </gazebo>
</robot>

